<?xml version="1.0" encoding="utf-8"?>

<robot name="galileo_mini15">
    <mujoco>
        <compiler 
        meshdir="../meshes/" 
        balanceinertia="true" 
        discardvisual="false" />
  </mujoco>
  <link name="world" />
  <joint name="floating_base_joint" type="floating">
    <origin xyz="0 0 0" rpy="0 0 0" />
    <parent link="world" />
    <child link="base_link" />
  </joint>
  <link name="base_link">
    <inertial>
      <origin xyz="0.01435 0.0040863 0.0010607" rpy="0 0 0" />
      <mass value="16.057" />
      <inertia
        ixx="0.082348"
        iyy="0.407373"
        izz="0.445820"
        ixy="0.000713"
        ixz="0.022641"
        iyz="-0.000244" />
    </inertial>
    <visual>
      <origin xyz="0 0 0" rpy="0 0 0" />
      <geometry>
        <mesh filename="package://galileo_mini15_description/meshes/trunk.STL" scale="1 1 1" />
      </geometry>
      <material name="">
        <color rgba="0.8 0.4 0 1" />
      </material>
    </visual>
    <collision>
      <origin xyz="0 0 0" rpy="0 0 0" />
      <geometry>
        <mesh filename="package://galileo_mini15_description/meshes/trunk.STL" scale="1 1 1" />
      </geometry>
    </collision>
  </link>

  <!-- ****************************FR**************************** -->

  <link name="FR_abd_link">
    <inertial>
      <origin xyz="0.074261 -0.010662 0.00797" rpy="0 0 0" />
      <mass value="1.748" />
      <inertia ixx="0.000667447" iyy="0.00144482" izz="0.00107312" ixy="7.2909e-05"
        ixz="-1.0214e-05" iyz="-5.08e-08" />
    </inertial>
    <visual>
      <origin xyz="0 0 0" rpy="0 0 0" />
      <geometry>
        <mesh filename="package://galileo_mini15_description/meshes/FL_abd_link.STL"
          scale="1.0 -1.0 1.0" />
      </geometry>
      <material name="">
        <color rgba="1 0.4 0.4 1" />
      </material>
    </visual>
    <collision>
      <origin xyz="0 0 0" rpy="0 0 0" />
      <geometry>
        <mesh filename="package://galileo_mini15_description/meshes/FL_abd_link.STL"
          scale="1.0 -1.0 1.0" />
      </geometry>
    </collision>
  </link>

  <joint name="FR_abd_joint" type="revolute">
    <origin xyz="0.2065 -0.065 0.0" rpy="-0.0 0.0 -0.0" />
    <parent link="base_link" />
    <child link="FR_abd_link" />
    <axis xyz="1 0 0" />
    <limit lower="-0.80285" upper="0.80285" effort="100" velocity="21" />
  </joint>

  <link name="FR_hip_link">
    <inertial>
      <origin xyz="-0.0014 0.0344 -0.0174" rpy="0 0 0" />
      <mass value="2.22606" />
      <inertia ixx="0.009416249" iyy="0.0090907891" izz="0.0023041271" ixy="-0.0001223515"
        ixz="-0.0004705786" iyz="-0.0013313752" />
    </inertial>
    <visual>
      <origin xyz="0 0 0" rpy="0 0 0" />
      <geometry>
        <mesh filename="package://galileo_mini15_description/meshes/FL_hip_link.STL"
          scale="1.0 -1.0 1.0" />
      </geometry>
      <material name="">
        <color rgba="1 1 0.4 1" />
      </material>
    </visual>
    <collision>
      <origin xyz="0 0 0" rpy="0 0 0" />
      <geometry>
        <mesh filename="package://galileo_mini15_description/meshes/FL_hip_link.STL"
          scale="1.0 -1.0 1.0" />
      </geometry>
    </collision>
  </link>

  <joint name="FR_hip_joint" type="revolute">
    <origin xyz="0.08 -0.119 0.0" rpy="-0.0 0.0 -0.0" />
    <parent link="FR_abd_link" />
    <child link="FR_hip_link" />
    <axis xyz="0 1 0" />
    <limit lower="-4.1888" upper="1.0472" effort="100" velocity="21" />
  </joint>

  <link name="FR_knee_link">
    <inertial>
      <origin xyz="0.0034 0.0105 -0.13" rpy="0 0 0" />
      <mass value="0.3261" />
      <inertia ixx="0.0046064111" iyy="0.0046485626" izz="8.17992e-05" ixy="9.9e-09"
        ixz="1.8937e-06" iyz="4.4248e-06" />
    </inertial>
    <visual>
      <origin xyz="0 0 0" rpy="0 0 0" />
      <geometry>
        <mesh filename="package://galileo_mini15_description/meshes/FL_knee_link.STL"
          scale="1.0 -1.0 1.0" />
      </geometry>
      <material name="">
        <color rgba="0.4 1 0.4 1" />
      </material>
    </visual>
    <collision>
      <origin xyz="0 0 0" rpy="0 0 0" />
      <geometry>
        <mesh filename="package://galileo_mini15_description/meshes/FL_knee_link.STL"
          scale="1.0 -1.0 1.0" />
      </geometry>
    </collision>
  </link>

  <joint name="FR_knee_joint" type="revolute">
    <origin xyz="0.0 -0.01 -0.26" rpy="-0.0 0.0 -0.0" />
    <parent link="FR_hip_link" />
    <child link="FR_knee_link" />
    <axis xyz="0 1 0" />
    <limit lower="-2.6965" upper="-0.9163" effort="150" velocity="21" />
  </joint>

  <link name="FR_foot_link">
    <inertial>
      <origin xyz="0.001 0 0.002" rpy="0 0 0" />
      <mass
        value="0.01020487" />
      <inertia
        ixx="5.496E-08"
        ixy="0"
        ixz="1.7152E-40"
        iyy="5.496E-08"
        iyz="0"
        izz="5.496E-08" />
    </inertial>
    <visual>
      <origin xyz="-0.04 0.0105 -0.006" rpy="0 0 0" />
      <geometry>
        <sphere radius="0.025" />
      </geometry>
      <material name="">
        <color rgba="1 1 1 1" />
      </material>
    </visual>
    <collision>
      <origin xyz="-0.04 0.0105 -0.006" rpy="0 0 0" />
      <geometry>
        <sphere radius="0.025" />
      </geometry>
    </collision>
  </link>

  <joint name="FR_foot_joint" type="fixed" dont_collapse="true">
    <origin xyz="0.032939 -0.0 -0.26149" rpy="-0.0 0.0 -0.0" />
    <parent link="FR_knee_link" />
    <child link="FR_foot_link" />
    <axis xyz="0 1 0" />
    <limit lower="0" upper="0" effort="0" velocity="0" />
  </joint>

  <!-- ****************************HR**************************** -->
  <link name="HR_abd_link">
    <inertial>
      <origin xyz="0.074261 -0.010662 0.00797" rpy="0 0 0" />
      <mass value="1.748" />
      <inertia ixx="0.000667447" iyy="0.00144482" izz="0.00107312" ixy="-7.2909e-05"
        ixz="1.0214e-05" iyz="-5.08e-08" />
    </inertial>
    <visual>
      <origin xyz="0 0 0" rpy="0 0 0" />
      <geometry>
        <mesh filename="package://galileo_mini15_description/meshes/RL_abd_link.STL"
          scale="1.0 -1.0 1.0" />
      </geometry>
      <material name="">
        <color rgba="0.8 1.0 0.8 1" />
      </material>
    </visual>
    <collision>
      <origin xyz="0 0 0" rpy="0 0 0" />
      <geometry>
        <mesh filename="package://galileo_mini15_description/meshes/RL_abd_link.STL"
          scale="1.0 -1.0 1.0" />
      </geometry>
    </collision>
  </link>

  <joint name="HR_abd_joint" type="revolute">
    <origin xyz="-0.2065 -0.065 0.0" rpy="-0.0 0.0 -0.0" />
    <parent link="base_link" />
    <child link="HR_abd_link" />
    <axis xyz="1 0 0" />
    <limit lower="-0.80285" upper="0.80285" effort="100" velocity="21" />
  </joint>

  <link name="HR_hip_link">
    <inertial>
      <origin xyz="-0.0014 0.0344 -0.0174" rpy="0 0 0" />
      <mass value="2.22606" />
      <inertia ixx="0.009416249" iyy="0.0090907891" izz="0.0023041271" ixy="-0.0001223515"
        ixz="-0.0004705786" iyz="-0.0013313752" />
    </inertial>
    <visual>
      <origin xyz="0 0 0" rpy="0 0 0" />
      <geometry>
        <mesh filename="package://galileo_mini15_description/meshes/RL_hip_link.STL"
          scale="1.0 -1.0 1.0" />
      </geometry>
      <material name="">
        <color rgba="1 0.5 1 1" />
      </material>
    </visual>
    <collision>
      <origin xyz="0 0 0" rpy="0 0 0" />
      <geometry>
        <mesh filename="package://galileo_mini15_description/meshes/RL_hip_link.STL"
          scale="1.0 -1.0 1.0" />
      </geometry>
    </collision>
  </link>

  <joint name="HR_hip_joint" type="revolute">
    <origin xyz="-0.08 -0.119 0.0" rpy="-0.0 0.0 -0.0" />
    <parent link="HR_abd_link" />
    <child link="HR_hip_link" />
    <axis xyz="0 1 0" />
    <limit lower="-4.1888" upper="1.0472" effort="100" velocity="21" />
  </joint>

  <link name="HR_knee_link">
    <inertial>
      <origin xyz="0.0034 0.0105 -0.13" rpy="0 0 0" />
      <mass value="0.3261" />
      <inertia ixx="0.0046064111" iyy="0.0046485626" izz="8.17992e-05" ixy="9.9e-09"
        ixz="1.8937e-06" iyz="4.4248e-06" />
    </inertial>
    <visual>
      <origin xyz="0 0 0" rpy="0 0 0" />
      <geometry>
        <mesh filename="package://galileo_mini15_description/meshes/RL_knee_link.STL"
          scale="1.0 -1.0 1.0" />
      </geometry>
      <material name="">
        <color rgba="1 0.4 0.4 1" />
      </material>
    </visual>
    <collision>
      <origin xyz="0 0 0" rpy="0 0 0" />
      <geometry>
        <mesh filename="package://galileo_mini15_description/meshes/RL_knee_link.STL"
          scale="1.0 -1.0 1.0" />
      </geometry>
    </collision>
  </link>

  <joint name="HR_knee_joint" type="revolute">
    <origin xyz="0.0 -0.01 -0.26" rpy="-0.0 0.0 -0.0" />
    <parent link="HR_hip_link" />
    <child link="HR_knee_link" />
    <axis xyz="0 1 0" />
    <limit lower="-2.6965" upper="-0.9163" effort="150" velocity="21" />
  </joint>

  <link name="HR_foot_link">
    <inertial>
      <origin xyz="0.001 0 0.002" rpy="0 0 0" />
      <mass
        value="0.010204873572147578" />
      <inertia
        ixx="5.49600066619755E-08"
        ixy="0"
        ixz="5.28443143791483E-42"
        iyy="5.49600066619755E-08"
        iyz="0"
        izz="5.49600066619755E-08" />
    </inertial>
    <visual>
      <origin xyz="-0.04 0.0105 -0.006" rpy="0 0 0" />
      <geometry>
        <sphere radius="0.025" />
      </geometry>
      <material name="">
        <color rgba="1 1 1 1" />
      </material>
    </visual>
    <collision>
      <origin xyz="-0.04 0.0105 -0.006" rpy="0 0 0" />
      <geometry>
        <sphere radius="0.025" />
      </geometry>
    </collision>
  </link>

  <joint name="HR_foot_joint" type="fixed" dont_collapse="true">
    <origin xyz="0.032939 -0.0 -0.26149" rpy="-0.0 0.0 -0.0" />
    <parent link="HR_knee_link" />
    <child link="HR_foot_link" />
    <axis xyz="0 1 0" />
    <limit lower="0" upper="0" effort="0" velocity="0" />
  </joint>

  <!-- ****************************FL**************************** -->

  <link name="FL_abd_link">
    <inertial>
      <origin xyz="0.074261 0.010662 0.00797" rpy="0 0 0" />
      <mass value="1.748" />
      <inertia ixx="0.000667447" iyy="0.00144482" izz="0.00107312" ixy="-7.2909e-05"
        ixz="-1.0214e-05" iyz="5.08e-08" />
    </inertial>
    <visual>
      <origin xyz="0 0 0" rpy="0 0 0" />
      <geometry>
        <mesh filename="package://galileo_mini15_description/meshes/FL_abd_link.STL" scale="1 1 1" />
      </geometry>
      <material name="">
        <color rgba="1 0.4 0.4 1" />
      </material>
    </visual>
    <collision>
      <origin xyz="0 0 0" rpy="0 0 0" />
      <geometry>
        <mesh filename="package://galileo_mini15_description/meshes/FL_abd_link.STL" scale="1 1 1" />
      </geometry>
    </collision>
  </link>

  <joint name="FL_abd_joint" type="revolute">
    <origin xyz="0.2065 0.065 0" rpy="0 0 0" />
    <parent link="base_link" />
    <child link="FL_abd_link" />
    <axis xyz="1 0 0" />
    <limit lower="-0.80285" upper="0.80285" effort="100" velocity="21" />
  </joint>

  <link name="FL_hip_link">
    <inertial>
      <origin xyz="-0.0014 -0.0344 -0.0174" rpy="0 0 0" />
      <mass value="2.22606" />
      <inertia ixx="0.009416249" iyy="0.0090907891" izz="0.0023041271" ixy="0.0001223515"
        ixz="-0.0004705786" iyz="0.0013313752" />
    </inertial>
    <visual>
      <origin xyz="0 0 0" rpy="0 0 0" />
      <geometry>
        <mesh filename="package://galileo_mini15_description/meshes/FL_hip_link.STL" scale="1 1 1" />
      </geometry>
      <material name="">
        <color rgba="1 1 0.4 1" />
      </material>
    </visual>
    <collision>
      <origin xyz="0 0 0" rpy="0 0 0" />
      <geometry>
        <mesh filename="package://galileo_mini15_description/meshes/FL_hip_link.STL" scale="1 1 1" />
      </geometry>
    </collision>
  </link>

  <joint name="FL_hip_joint" type="revolute">
    <origin xyz="0.08 0.119 0" rpy="0 0 0" />
    <parent link="FL_abd_link" />
    <child link="FL_hip_link" />
    <axis xyz="0 1 0" />
    <limit lower="-4.1888" upper="1.0472" effort="100" velocity="21" />
  </joint>

  <link name="FL_knee_link">
    <inertial>
      <origin xyz="0.0034 -0.0105 -0.13" rpy="0 0 0" />
      <mass value="0.3261" />
      <inertia ixx="0.0046064111" iyy="0.0046485626" izz="8.17992e-05" ixy="-9.9e-09"
        ixz="1.8937e-06" iyz="-4.4248e-06" />
    </inertial>
    <visual>
      <origin xyz="0 0 0" rpy="0 0 0" />
      <geometry>
        <mesh filename="package://galileo_mini15_description/meshes/FL_knee_link.STL" scale="1 1 1" />
      </geometry>
      <material name="">
        <color rgba="0.4 1 0.4 1" />
      </material>
    </visual>
    <collision>
      <origin xyz="0 0 0" rpy="0 0 0" />
      <geometry>
        <mesh filename="package://galileo_mini15_description/meshes/FL_knee_link.STL" scale="1 1 1" />
      </geometry>
    </collision>
  </link>

  <joint name="FL_knee_joint" type="revolute">
    <origin xyz="0 0.01 -0.26" rpy="0 0 0" />
    <parent link="FL_hip_link" />
    <child link="FL_knee_link" />
    <axis xyz="0 1 0" />
    <limit lower="-2.6965" upper="-0.9163" effort="150" velocity="21" />
  </joint>

  <link name="FL_foot_link">
    <inertial>
      <origin xyz="0.001 0 0.002" rpy="0 0 0" />
      <mass
        value="0.01020487" />
      <inertia
        ixx="5.496E-08"
        ixy="-2.0392E-56"
        ixz="0"
        iyy="5.496E-08"
        iyz="0"
        izz="5.496E-08" />
    </inertial>
    <visual>
      <origin xyz="-0.04 -0.0105 -0.006" rpy="0 0 0" />
      <geometry>
        <sphere radius="0.025" />
      </geometry>
      <material name="">
        <color rgba="1 1 1 1" />
      </material>
    </visual>
    <collision>
      <origin xyz="-0.04 -0.0105 -0.006" rpy="0 0 0" />
      <geometry>
        <sphere radius="0.025" />
      </geometry>
    </collision>
  </link>

  <joint name="FL_foot_joint" type="fixed" dont_collapse="true">
    <origin xyz="0.032939 0 -0.26149" rpy="0 0 0" />
    <parent link="FL_knee_link" />
    <child link="FL_foot_link" />
    <axis xyz="0 1 0" />
    <limit lower="0" upper="0" effort="0" velocity="0" />
  </joint>

  <!-- ****************************HL**************************** -->

  <link name="HL_abd_link">
    <inertial>
      <origin xyz="0.074261 0.010662 0.00797" rpy="0 0 0" />
      <mass value="1.748" />
      <inertia ixx="0.000667447" iyy="0.00144482" izz="0.00107312" ixy="7.2909e-05" ixz="1.0214e-05"
        iyz="5.08e-08" />
    </inertial>
    <visual>
      <origin xyz="0 0 0" rpy="0 0 0" />
      <geometry>
        <mesh filename="package://galileo_mini15_description/meshes/RL_abd_link.STL" scale="1 1 1" />
      </geometry>
      <material name="">
        <color rgba="0.8 1.0 0.8 1" />
      </material>
    </visual>
    <collision>
      <origin xyz="0 0 0" rpy="0 0 0" />
      <geometry>
        <mesh filename="package://galileo_mini15_description/meshes/RL_abd_link.STL" scale="1 1 1" />
      </geometry>
    </collision>
  </link>

  <joint name="HL_abd_joint" type="revolute">
    <origin xyz="-0.2065 0.065 0" rpy="0 0 0" />
    <parent link="base_link" />
    <child link="HL_abd_link" />
    <axis xyz="1 0 0" />
    <limit lower="-0.80285" upper="0.80285" effort="100" velocity="21" />
  </joint>

  <link name="HL_hip_link">
    <inertial>
      <origin xyz="-0.0014 -0.0344 -0.0174" rpy="0 0 0" />
      <mass value="2.22606" />
      <inertia ixx="0.009416249" iyy="0.0090907891" izz="0.0023041271" ixy="0.0001223515"
        ixz="-0.0004705786" iyz="0.0013313752" />
    </inertial>
    <visual>
      <origin xyz="0 0 0" rpy="0 0 0" />
      <geometry>
        <mesh filename="package://galileo_mini15_description/meshes/RL_hip_link.STL" scale="1 1 1" />
      </geometry>
      <material name="">
        <color rgba="1 0.5 1 1" />
      </material>
    </visual>
    <collision>
      <origin xyz="0 0 0" rpy="0 0 0" />
      <geometry>
        <mesh filename="package://galileo_mini15_description/meshes/RL_hip_link.STL" scale="1 1 1" />
      </geometry>
    </collision>
  </link>

  <joint name="HL_hip_joint" type="revolute">
    <origin xyz="-0.08 0.119 0" rpy="0 0 0" />
    <parent link="HL_abd_link" />
    <child link="HL_hip_link" />
    <axis xyz="0 1 0" />
    <limit lower="-4.1888" upper="1.0472" effort="100" velocity="21" />
  </joint>

  <link name="HL_knee_link">
    <inertial>
      <origin xyz="0.0034 -0.0105 -0.13" rpy="0 0 0" />
      <mass value="0.3261" />
      <inertia ixx="0.0046064111" iyy="0.0046485626" izz="8.17992e-05" ixy="-9.9e-09"
        ixz="1.8937e-06" iyz="-4.4248e-06" />
    </inertial>
    <visual>
      <origin xyz="0 0 0" rpy="0 0 0" />
      <geometry>
        <mesh filename="package://galileo_mini15_description/meshes/RL_knee_link.STL" scale="1 1 1" />
      </geometry>
      <material name="">
        <color rgba="1 0.4 0.4 1" />
      </material>
    </visual>
    <collision>
      <origin xyz="0 0 0" rpy="0 0 0" />
      <geometry>
        <mesh filename="package://galileo_mini15_description/meshes/RL_knee_link.STL" scale="1 1 1" />
      </geometry>
    </collision>
  </link>

  <joint name="HL_knee_joint" type="revolute">
    <origin xyz="0 0.01 -0.26" rpy="0 0 0" />
    <parent link="HL_hip_link" />
    <child link="HL_knee_link" />
    <axis xyz="0 1 0" />
    <limit lower="-2.6965" upper="-0.9163" effort="150" velocity="21" />
  </joint>

  <link name="HL_foot_link">
    <inertial>
      <origin xyz="0.001 0 0.002" rpy="0 0 0" />
      <mass
        value="0.010204873572147578" />
      <inertia
        ixx="5.49600066619755E-08"
        ixy="0"
        ixz="7.97487625425431E-42"
        iyy="5.49600066619755E-08"
        iyz="0"
        izz="5.49600066619755E-08" />
    </inertial>
    <visual>
      <origin xyz="-0.04 -0.0105 -0.006" rpy="0 0 0" />
      <geometry>
        <sphere radius="0.025" />
      </geometry>
      <material name="">
        <color rgba="1 1 1 1" />
      </material>
    </visual>
    <collision>
      <origin xyz="-0.04 -0.0105 -0.006" rpy="0 0 0" />
      <geometry>
        <sphere radius="0.025" />
      </geometry>
    </collision>
  </link>

  <joint name="HL_foot_joint" type="fixed" dont_collapse="true">
    <origin xyz="0.032939 0 -0.26149" rpy="0 0 0" />
    <parent link="HL_knee_link" />
    <child link="HL_foot_link" />
    <axis xyz="0 1 0" />
    <limit lower="0" upper="0" effort="0" velocity="0" />
  </joint>

  <!-- ros2 control -->
  <ros2_control name="GalileoMiniSystem" type="system">
    <hardware>
      <plugin>hardware_mujoco/HardwareMujoco</plugin>
    </hardware>

    <joint name="FL_abd_joint">
      <command_interface name="position" />
      <command_interface name="velocity" />
      <command_interface name="effort" />
      <command_interface name="kp" />
      <command_interface name="kd" />
      <state_interface name="position" />
      <state_interface name="velocity" />
      <state_interface name="effort" />
    </joint>

    <joint name="FL_hip_joint">
      <command_interface name="position" />
      <command_interface name="velocity" />
      <command_interface name="effort" />
      <command_interface name="kp" />
      <command_interface name="kd" />
      <state_interface name="position" />
      <state_interface name="velocity" />
      <state_interface name="effort" />
    </joint>

    <joint name="FL_knee_joint">
      <command_interface name="position" />
      <command_interface name="velocity" />
      <command_interface name="effort" />
      <command_interface name="kp" />
      <command_interface name="kd" />
      <state_interface name="position" />
      <state_interface name="velocity" />
      <state_interface name="effort" />
    </joint>

    <joint name="FR_abd_joint">
      <command_interface name="position" />
      <command_interface name="velocity" />
      <command_interface name="effort" />
      <command_interface name="kp" />
      <command_interface name="kd" />
      <state_interface name="position" />
      <state_interface name="velocity" />
      <state_interface name="effort" />
    </joint>

    <joint name="FR_hip_joint">
      <command_interface name="position" />
      <command_interface name="velocity" />
      <command_interface name="effort" />
      <command_interface name="kp" />
      <command_interface name="kd" />
      <state_interface name="position" />
      <state_interface name="velocity" />
      <state_interface name="effort" />
    </joint>

    <joint name="FR_knee_joint">
      <command_interface name="position" />
      <command_interface name="velocity" />
      <command_interface name="effort" />
      <command_interface name="kp" />
      <command_interface name="kd" />
      <state_interface name="position" />
      <state_interface name="velocity" />
      <state_interface name="effort" />
    </joint>

    <joint name="HL_abd_joint">
      <command_interface name="position" />
      <command_interface name="velocity" />
      <command_interface name="effort" />
      <command_interface name="kp" />
      <command_interface name="kd" />
      <state_interface name="position" />
      <state_interface name="velocity" />
      <state_interface name="effort" />
    </joint>

    <joint name="HL_hip_joint">
      <command_interface name="position" />
      <command_interface name="velocity" />
      <command_interface name="effort" />
      <command_interface name="kp" />
      <command_interface name="kd" />
      <state_interface name="position" />
      <state_interface name="velocity" />
      <state_interface name="effort" />
    </joint>

    <joint name="HL_knee_joint">
      <command_interface name="position" />
      <command_interface name="velocity" />
      <command_interface name="effort" />
      <command_interface name="kp" />
      <command_interface name="kd" />
      <state_interface name="position" />
      <state_interface name="velocity" />
      <state_interface name="effort" />
    </joint>

    <joint name="HR_abd_joint">
      <command_interface name="position" />
      <command_interface name="velocity" />
      <command_interface name="effort" />
      <command_interface name="kp" />
      <command_interface name="kd" />
      <state_interface name="position" />
      <state_interface name="velocity" />
      <state_interface name="effort" />
    </joint>

    <joint name="HR_hip_joint">
      <command_interface name="position" />
      <command_interface name="velocity" />
      <command_interface name="effort" />
      <command_interface name="kp" />
      <command_interface name="kd" />
      <state_interface name="position" />
      <state_interface name="velocity" />
      <state_interface name="effort" />
    </joint>

    <joint name="HR_knee_joint">
      <command_interface name="position" />
      <command_interface name="velocity" />
      <command_interface name="effort" />
      <command_interface name="kp" />
      <command_interface name="kd" />
      <state_interface name="position" />
      <state_interface name="velocity" />
      <state_interface name="effort" />
    </joint>

    <sensor name="imu_sensor">
      <state_interface name="orientation.w" />
      <state_interface name="orientation.x" />
      <state_interface name="orientation.y" />
      <state_interface name="orientation.z" />
      <state_interface name="angular_velocity.x" />
      <state_interface name="angular_velocity.y" />
      <state_interface name="angular_velocity.z" />
      <state_interface name="linear_acceleration.x" />
      <state_interface name="linear_acceleration.y" />
      <state_interface name="linear_acceleration.z" />
    </sensor>

    <!-- <sensor name="foot_contact_sensor">
            <state_interface name="FR_foot_link" />
            <state_interface name="FL_foot_link" />
            <state_interface name="HR_foot_link" />
            <state_interface name="HL_foot_link" />
        </sensor> -->

  </ros2_control>
</robot>