<mujoco model="galileo_mini15">
  <compiler angle="radian" meshdir="../meshes/" autolimits="true" />

  <asset>
    <mesh name="base_link" file="trunk.STL" />
    <mesh name="FR_abd_link" file="FL_abd_link.STL" scale="1 -1 1" />
    <mesh name="FR_hip_link" file="FL_hip_link.STL" scale="1 -1 1" />
    <mesh name="FR_knee_link" file="FL_knee_link.STL" scale="1 -1 1" />
    <mesh name="HR_abd_link" file="RL_abd_link.STL" scale="1 -1 1" />
    <mesh name="HR_hip_link" file="RL_hip_link.STL" scale="1 -1 1" />
    <mesh name="HR_knee_link" file="RL_knee_link.STL" scale="1 -1 1" />
    <mesh name="FL_abd_link" file="FL_abd_link.STL" />
    <mesh name="FL_hip_link" file="FL_hip_link.STL" />
    <mesh name="FL_knee_link" file="FL_knee_link.STL" />
    <mesh name="HL_abd_link" file="RL_abd_link.STL" />
    <mesh name="HL_hip_link" file="RL_hip_link.STL" />
    <mesh name="HL_knee_link" file="RL_knee_link.STL" />
  </asset>

  <worldbody>
    <body name="base_link" pos="0 0 0.7">
      <inertial pos="0.01435 0.0040863 0.0010607"
        quat="-0.000902013 0.728669 -0.0025851 0.68486" mass="16.057"
        diaginertia="0.447226 0.407374 0.0809415" />
      <joint name="floating_base_joint" type="free" />
      <geom type="mesh" contype="0" conaffinity="0" group="1" density="0"
        rgba="0.75294 0.75294 0.75294 1" mesh="base_link" />
      <geom type="mesh" rgba="0.75294 0.75294 0.75294 1" mesh="base_link" />
      <site name="site_imu" pos="0 0 0" />

      <body name="FR_abd_link" pos="0.2065 -0.065 0">
        <inertial pos="0.074261 -0.010662 0.00797"
          quat="0.529655 0.515531 0.47108 0.481433" mass="1.748"
          diaginertia="0.0014516 0.00107337 0.000660418" />
        <joint name="FR_abd_joint" pos="0 0 0" axis="1 0 0" range="-0.80285 0.80285" />
        <geom type="mesh" contype="0" conaffinity="0" group="1" density="0"
          rgba="0.75294 0.75294 0.75294 1" mesh="FR_abd_link" />
        <geom type="mesh" rgba="0.75294 0.75294 0.75294 1" mesh="FR_abd_link" />
        <body name="FR_hip_link" pos="0.08 -0.119 0">
          <inertial pos="-0.0014 0.0344 -0.0174"
            quat="0.985102 -0.0970444 0.0193668 -0.140648" mass="2.22606"
            diaginertia="0.00945738 0.00933332 0.00202047" />
          <joint name="FR_hip_joint" pos="0 0 0" axis="0 1 0" range="-4.1888 1.0472" />
          <geom type="mesh" contype="0" conaffinity="0" group="1" density="0"
            rgba="0.75294 0.75294 0.75294 1" mesh="FR_hip_link" />
          <geom type="mesh" rgba="0.75294 0.75294 0.75294 1" mesh="FR_hip_link" />
          <body name="FR_knee_link" pos="0 -0.01 -0.26">
            <inertial pos="0.00432668 0.0101814 -0.133929"
              quat="0.728618 -0.00369805 -0.00253684 0.684905" mass="0.336305"
              diaginertia="0.00482398 0.00477364 9.17969e-05" />
            <joint name="FR_knee_joint" pos="0 0 0" axis="0 1 0" range="-2.6965 -0.9163" />
            <geom type="mesh" contype="0" conaffinity="0" group="1" density="0"
              rgba="0.75294 0.75294 0.75294 1" mesh="FR_knee_link" />
            <geom type="mesh" rgba="0.75294 0.75294 0.75294 1" mesh="FR_knee_link" />
            <geom size="0.025" pos="-0.007061 0.0105 -0.26749" contype="0" conaffinity="0" group="1"
              density="0" rgba="1 1 1 1" friction="0.7 0.02 0.01" />
            <geom name="FR_foot_link" size="0.025" pos="-0.007061 0.0105 -0.26749" rgba="1 1 1 1"
              friction="0.7 0.02 0.01" />
          </body>
        </body>
      </body>
      <body name="HR_abd_link" pos="-0.2065 -0.065 0">
        <inertial pos="0.074261 -0.010662 0.00797"
          quat="0.47108 0.481433 0.529655 0.515531" mass="1.748"
          diaginertia="0.0014516 0.00107337 0.000660418" />
        <joint name="HR_abd_joint" pos="0 0 0" axis="1 0 0" range="-0.80285 0.80285" />
        <geom type="mesh" contype="0" conaffinity="0" group="1" density="0"
          rgba="0.75294 0.75294 0.75294 1" mesh="HR_abd_link" />
        <geom type="mesh" rgba="0.75294 0.75294 0.75294 1" mesh="HR_abd_link" />
        <body name="HR_hip_link" pos="-0.08 -0.119 0">
          <inertial pos="-0.0014 0.0344 -0.0174"
            quat="0.985102 -0.0970444 0.0193668 -0.140648" mass="2.22606"
            diaginertia="0.00945738 0.00933332 0.00202047" />
          <joint name="HR_hip_joint" pos="0 0 0" axis="0 1 0" range="-4.1888 1.0472" />
          <geom type="mesh" contype="0" conaffinity="0" group="1" density="0"
            rgba="0.75294 0.75294 0.75294 1" mesh="HR_hip_link" />
          <geom type="mesh" rgba="0.75294 0.75294 0.75294 1" mesh="HR_hip_link" />
          <body name="HR_knee_link" pos="0 -0.01 -0.26">
            <inertial pos="0.00432668 0.0101814 -0.133929"
              quat="0.728618 -0.00369805 -0.00253684 0.684905" mass="0.336305"
              diaginertia="0.00482398 0.00477364 9.17969e-05" />
            <joint name="HR_knee_joint" pos="0 0 0" axis="0 1 0" range="-2.6965 -0.9163" />
            <geom type="mesh" contype="0" conaffinity="0" group="1" density="0"
              rgba="0.75294 0.75294 0.75294 1" mesh="HR_knee_link" />
            <geom type="mesh" rgba="0.75294 0.75294 0.75294 1" mesh="HR_knee_link" />
            <geom size="0.025" pos="-0.007061 0.0105 -0.26749" contype="0" conaffinity="0" group="1"
              density="0" rgba="1 1 1 1" friction="0.7 0.02 0.01" />
            <geom size="0.025" pos="-0.007061 0.0105 -0.26749" rgba="1 1 1 1"
              friction="0.7 0.02 0.01" />
          </body>
        </body>
      </body>
      <body name="FL_abd_link" pos="0.2065 0.065 0">
        <inertial pos="0.074261 0.010662 0.00797"
          quat="0.481433 0.47108 0.515531 0.529655" mass="1.748"
          diaginertia="0.0014516 0.00107337 0.000660418" />
        <joint name="FL_abd_joint" pos="0 0 0" axis="1 0 0" range="-0.80285 0.80285" />
        <geom type="mesh" contype="0" conaffinity="0" group="1" density="0"
          rgba="0.75294 0.75294 0.75294 1" mesh="FL_abd_link" />
        <geom type="mesh" rgba="0.75294 0.75294 0.75294 1" mesh="FL_abd_link" />
        <body name="FL_hip_link" pos="0.08 0.119 0">
          <inertial pos="-0.0014 -0.0344 -0.0174"
            quat="0.985102 0.0970444 0.0193668 0.140648" mass="2.22606"
            diaginertia="0.00945738 0.00933332 0.00202047" />
          <joint name="FL_hip_joint" pos="0 0 0" axis="0 1 0" range="-4.1888 1.0472" />
          <geom type="mesh" contype="0" conaffinity="0" group="1" density="0"
            rgba="0.75294 0.75294 0.75294 1" mesh="FL_hip_link" />
          <geom type="mesh" rgba="0.75294 0.75294 0.75294 1" mesh="FL_hip_link" />
          <body name="FL_knee_link" pos="0 0.01 -0.26">
            <inertial pos="0.00432668 -0.0101814 -0.133929"
              quat="0.684905 -0.00253684 -0.00369805 0.728618" mass="0.336305"
              diaginertia="0.00482398 0.00477364 9.17969e-05" />
            <joint name="FL_knee_joint" pos="0 0 0" axis="0 1 0" range="-2.6965 -0.9163" />
            <geom type="mesh" contype="0" conaffinity="0" group="1" density="0"
              rgba="0.75294 0.75294 0.75294 1" mesh="FL_knee_link" />
            <geom type="mesh" rgba="0.75294 0.75294 0.75294 1" mesh="FL_knee_link" />
            <geom size="0.025" pos="-0.007061 -0.0105 -0.26749" contype="0" conaffinity="0"
              group="1" density="0" rgba="1 1 1 1" friction="0.7 0.02 0.01" />
            <geom name="FL_foot_link" size="0.025" pos="-0.007061 -0.0105 -0.26749"
              rgba="1 1 1 1" friction="0.7 0.02 0.01" />
          </body>
        </body>
      </body>
      <body name="HL_abd_link" pos="-0.2065 0.065 0">
        <inertial pos="0.074261 0.010662 0.00797"
          quat="0.515531 0.529655 0.481433 0.47108" mass="1.748"
          diaginertia="0.0014516 0.00107337 0.000660418" />
        <joint name="HL_abd_joint" pos="0 0 0" axis="1 0 0" range="-0.80285 0.80285" />
        <geom type="mesh" contype="0" conaffinity="0" group="1" density="0"
          rgba="0.75294 0.75294 0.75294 1" mesh="HL_abd_link" />
        <geom type="mesh" rgba="0.75294 0.75294 0.75294 1" mesh="HL_abd_link" />
        <body name="HL_hip_link" pos="-0.08 0.119 0">
          <inertial pos="-0.0014 -0.0344 -0.0174"
            quat="0.985102 0.0970444 0.0193668 0.140648" mass="2.22606"
            diaginertia="0.00945738 0.00933332 0.00202047" />
          <joint name="HL_hip_joint" pos="0 0 0" axis="0 1 0" range="-4.1888 1.0472" />
          <geom type="mesh" contype="0" conaffinity="0" group="1" density="0"
            rgba="0.75294 0.75294 0.75294 1" mesh="HL_hip_link" />
          <geom type="mesh" rgba="0.75294 0.75294 0.75294 1" mesh="HL_hip_link" />
          <body name="HL_knee_link" pos="0 0.01 -0.26">
            <inertial pos="0.00432668 -0.0101814 -0.133929"
              quat="0.684905 -0.00253684 -0.00369805 0.728618" mass="0.336305"
              diaginertia="0.00482398 0.00477364 9.17969e-05" />
            <joint name="HL_knee_joint" pos="0 0 0" axis="0 1 0" range="-2.6965 -0.9163" />
            <geom type="mesh" contype="0" conaffinity="0" group="1" density="0"
              rgba="0.75294 0.75294 0.75294 1" mesh="HL_knee_link" />
            <geom type="mesh" rgba="0.75294 0.75294 0.75294 1" mesh="HL_knee_link" />
            <geom size="0.025" pos="-0.007061 -0.0105 -0.26749" contype="0" conaffinity="0"
              group="1" density="0" rgba="1 1 1 1" friction="0.7 0.02 0.01" />
            <geom name="HL_foot_link" size="0.025" pos="-0.007061 -0.0105 -0.26749" rgba="1 1 1 1"
              friction="0.7 0.02 0.01" />
          </body>
        </body>
      </body>
    </body>
  </worldbody>

  <actuator>
    <motor name="FR_abd_joint" joint="FR_abd_joint" gear="1" ctrllimited="true"
      ctrlrange="-180 180" />
    <motor name="HR_abd_joint" joint="HR_abd_joint" gear="1" ctrllimited="true"
      ctrlrange="-180 180" />
    <motor name="FL_abd_joint" joint="FL_abd_joint" gear="1" ctrllimited="true"
      ctrlrange="-180 180" />
    <motor name="HL_abd_joint" joint="HL_abd_joint" gear="1" ctrllimited="true"
      ctrlrange="-180 180" />

    <motor name="FR_hip_joint" joint="FR_hip_joint" gear="1" ctrllimited="true"
      ctrlrange="-180 180" />
    <motor name="HR_hip_joint" joint="HR_hip_joint" gear="1" ctrllimited="true"
      ctrlrange="-180 180" />
    <motor name="FL_hip_joint" joint="FL_hip_joint" gear="1" ctrllimited="true"
      ctrlrange="-180 180" />
    <motor name="HL_hip_joint" joint="HL_hip_joint" gear="1" ctrllimited="true"
      ctrlrange="-180 180" />

    <motor name="FR_knee_joint" joint="FR_knee_joint" gear="1" ctrllimited="true"
      ctrlrange="-180 180" />
    <motor name="HR_knee_joint" joint="HR_knee_joint" gear="1" ctrllimited="true"
      ctrlrange="-180 180" />
    <motor name="FL_knee_joint" joint="FL_knee_joint" gear="1" ctrllimited="true"
      ctrlrange="-180 180" />
    <motor name="HL_knee_joint" joint="HL_knee_joint" gear="1" ctrllimited="true"
      ctrlrange="-180 180" />
  </actuator>

  <sensor>
    <framequat name="imu_quat" objtype="site" objname="site_imu" />
    <accelerometer name="imu_acc" site="site_imu" />
    <gyro name="imu_gyro" site="site_imu" />
  </sensor>

  <contact>
    <exclude body1="base_link" body2="FR_abd_link" />
    <exclude body1="base_link" body2="HR_abd_link" />
    <exclude body1="base_link" body2="FL_abd_link" />
    <exclude body1="base_link" body2="HL_abd_link" />
    <exclude body1="base_link" body2="FR_hip_link" />
    <exclude body1="base_link" body2="HR_hip_link" />
    <exclude body1="base_link" body2="FL_hip_link" />
    <exclude body1="base_link" body2="HL_hip_link" />
  </contact>

  <keyframe>
    <key name="stand"
      qpos="0 0 0.40 1 0 0 0 0 0.72 -1.44 0 0.72 -1.44 0 0.72 -1.44 0 0.72 -1.44" />
    <key name="down"
      qpos="0 0 0.40 1 0 0 0 -0.5 1.05 -2.46 -0.5 1.05 -2.46 0.5 1.05 -2.46 0.5 1.05 -2.46" />
  </keyframe>
</mujoco>