<mujoco model="JLL_ROBOT">
    <compiler angle='radian' eulerseq="XYZ" meshdir="../meshes/" autolimits="true" />
    <option timestep="0.001" integrator="RK4" />

    <asset>
        <texture type="skybox" builtin="gradient" rgb1=".3 .5 .7" rgb2="0 0 0" width="32"
            height="512" />
        <texture name="body" type="cube" builtin="flat" mark="cross" width="127" height="1278"
            rgb1="0.8 0.6 0.4" rgb2="0.8 0.6 0.4" markrgb="1 1 1" random="0.01" />
        <material name="body" texture="body" texuniform="true" rgba="0.8 0.6 .4 1" />
        <texture name="grid" type="2d" builtin="checker" width="512" height="512" rgb1=".1 .2 .3"
            rgb2=".2 .3 .4" />
        <material name="grid" texture="grid" texrepeat="1 1" texuniform="true" reflectance=".2" />
    </asset>

    <asset>
        <mesh name="base_link_mesh_visual" file="../meshes/trunk.STL" scale='1 1 1' />
        <mesh name="base_link_mesh_collision" file="../meshes/trunk.STL" scale='1 1 1' />
        <mesh name="left_front_abad_mesh_visual" file="../meshes/FL_abd_link.STL" scale='1 1 1' />
        <mesh name="left_front_abad_mesh_collision" file="../meshes/FL_abd_link.STL" scale='1 1 1' />
        <mesh name="left_front_hip_mesh_visual" file="../meshes/FL_hip_link.STL" scale='1 1 1' />
        <mesh name="left_front_hip_mesh_collision" file="../meshes/FL_hip_link.STL" scale='1 1 1' />
        <mesh name="left_front_knee_mesh_visual" file="../meshes/FL_knee_link.STL" scale='1 1 1' />
        <mesh name="left_front_knee_mesh_collision" file="../meshes/FL_knee_link.STL" scale='1 1 1' />
        <mesh name="left_rear_abad_mesh_visual" file="../meshes/RL_abd_link.STL" scale='1 1 1' />
        <mesh name="left_rear_abad_mesh_collision" file="../meshes/RL_abd_link.STL" scale='1 1 1' />
        <mesh name="left_rear_hip_mesh_visual" file="../meshes/RL_hip_link.STL" scale='1 1 1' />
        <mesh name="left_rear_hip_mesh_collision" file="../meshes/RL_hip_link.STL" scale='1 1 1' />
        <mesh name="left_rear_knee_mesh_visual" file="../meshes/RL_knee_link.STL" scale='1 1 1' />
        <mesh name="left_rear_knee_mesh_collision" file="../meshes/RL_knee_link.STL" scale='1 1 1' />
        <mesh name="right_front_abad_mesh_visual" file="../meshes/FL_abd_link.STL"
            scale='1.0 -1.0 1.0' />
        <mesh name="right_front_abad_mesh_collision" file="../meshes/FL_abd_link.STL"
            scale='1.0 -1.0 1.0' />
        <mesh name="right_front_hip_mesh_visual" file="../meshes/FL_hip_link.STL"
            scale='1.0 -1.0 1.0' />
        <mesh name="right_front_hip_mesh_collision" file="../meshes/FL_hip_link.STL"
            scale='1.0 -1.0 1.0' />
        <mesh name="right_front_knee_mesh_visual" file="../meshes/FL_knee_link.STL"
            scale='1.0 -1.0 1.0' />
        <mesh name="right_front_knee_mesh_collision" file="../meshes/FL_knee_link.STL"
            scale='1.0 -1.0 1.0' />
        <mesh name="right_rear_abad_mesh_visual" file="../meshes/RL_abd_link.STL"
            scale='1.0 -1.0 1.0' />
        <mesh name="right_rear_abad_mesh_collision" file="../meshes/RL_abd_link.STL"
            scale='1.0 -1.0 1.0' />
        <mesh name="right_rear_hip_mesh_visual" file="../meshes/RL_hip_link.STL"
            scale='1.0 -1.0 1.0' />
        <mesh name="right_rear_hip_mesh_collision" file="../meshes/RL_hip_link.STL"
            scale='1.0 -1.0 1.0' />
        <mesh name="right_rear_knee_mesh_visual" file="../meshes/RL_knee_link.STL"
            scale='1.0 -1.0 1.0' />
        <mesh name="right_rear_knee_mesh_collision" file="../meshes/RL_knee_link.STL"
            scale='1.0 -1.0 1.0' />
        <!-- asset auto generate -->
    </asset>

    <worldbody>
        <geom name="floor" type="plane" size="0 0 0.05" material="grid" />
        <light pos="0 0 1.5" dir="0 0 -1" directional="true" />

        <body name='base_link' pos='0 0 1.0' euler='0 0 0'>
            <inertial pos="0.01435 0.0040863 0.0010607" mass="16.057"
                fullinertia="0.082348 0.407373 0.445820 0.000713 0.022641 -0.000244" />
            <freejoint />
            <site name="imu" size="0.01" pos="0 0 0" />
            <geom type='mesh' mesh='base_link_mesh_visual' pos='0 0 0' euler='0 0 0'
                rgba="0.8 0.4 0 1" />
            <geom type='mesh' mesh='base_link_mesh_collision' pos='0 0 0' euler='0 0 0' contype="0"
                conaffinity="0" group="1" density="0" />
            <!-- base_link site geom -->

            <body name='left_front_abad' pos='0.2065 0.065 0' euler='0 0 0'>
                <inertial pos="0.074261 0.010662 0.00797" mass="1.748"
                    fullinertia="0.000667447 0.00144482 0.00107312 -7.2909e-05 -1.0214e-05 5.08e-08" />
                <joint name='FL_abd_joint' type='hinge' axis='1 0 0' limited='true'
                    range='-0.80285 0.80285' damping='1' />
                <geom type='mesh' mesh='left_front_abad_mesh_visual' pos='0 0 0' euler='0 0 0'
                    rgba="1 0.4 0.4 1" />
                <geom type='mesh' mesh='left_front_abad_mesh_collision' pos='0 0 0' euler='0 0 0'
                    contype="0" conaffinity="0" group="1" density="0" />
                <!-- left_front_abad site geom -->

                <body name='left_front_hip' pos='0.08 0.119 0' euler='0 0 0'>
                    <inertial pos="-0.0014 -0.0344 -0.0174" mass="2.22606"
                        fullinertia="0.009416249 0.0090907891 0.0023041271 0.0001223515 -0.0004705786 0.0013313752" />
                    <joint name='FL_hip_joint' type='hinge' axis='0 1 0' limited='true'
                        range='-1.0472 4.1888' damping='1' />
                    <geom type='mesh' mesh='left_front_hip_mesh_visual' pos='0 0 0' euler='0 0 0'
                        rgba="1 1 0.4 1" />
                    <geom type='mesh' mesh='left_front_hip_mesh_collision' pos='0 0 0' euler='0 0 0'
                        contype="0" conaffinity="0" group="1" density="0" />
                    <!-- left_front_hip site geom -->

                    <body name='left_front_knee' pos='0 0.01 -0.26' euler='0 0 0'>
                        <inertial pos="0.0034 -0.0105 -0.13" mass="0.3261"
                            fullinertia="0.0046064111 0.0046485626 8.17992e-05 -9.9e-09 1.8937e-06 -4.4248e-06" />
                        <joint name='FL_knee_joint' type='hinge' axis='0 1 0' limited='true'
                            range='-2.6965 -0.9163' damping='1' />
                        <geom type='mesh' mesh='left_front_knee_mesh_visual' pos='0 0 0'
                            euler='0 0 0' rgba="0.4 1 0.4 1" friction="0.7 0.02 0.01" />
                        <geom type='mesh' mesh='left_front_knee_mesh_collision' pos='0 0 0'
                            euler='0 0 0' contype="0" conaffinity="0" group="1" density="0"
                            friction="0.7 0.02 0.01" />
                        <!-- left_front_knee site geom -->

                        <body name='FL_foot_link' pos='0.0 -0.01 -0.26149' euler='0 0 0'>
                            <inertial pos="0 0 0" mass="0.000204873572147578"
                                fullinertia="1.09600066619755e-09 1.09600066619755e-09 1.09600066619755e-09 0 0 0" />
                            <geom type='sphere' size='0.035'
                                euler='0 0 0' rgba='0 0.5 1 1' />
                            <geom type='sphere' size='0.035'
                                euler='0 0 0' contype="0" conaffinity="0" group="1" density="0" />
                        </body>
                        <!-- left_front_knee child body -->
                    </body>
                    <!-- left_front_hip child body -->
                </body>
                <!-- left_front_abad child body -->
            </body>

            <body name='left_rear_abad' pos='-0.2065 0.065 0' euler='0 0 0'>
                <inertial pos="0.074261 0.010662 0.00797" mass="1.748"
                    fullinertia="0.000667447 0.00144482 0.00107312 7.2909e-05 1.0214e-05 5.08e-08" />
                <joint name='HL_abd_joint' type='hinge' axis='1 0 0' limited='true'
                    range='-0.80285 0.80285' damping='1' />
                <geom type='mesh' mesh='left_rear_abad_mesh_visual' pos='0 0 0' euler='0 0 0'
                    rgba="0.8 1.0 0.8 1" />
                <geom type='mesh' mesh='left_rear_abad_mesh_collision' pos='0 0 0' euler='0 0 0'
                    contype="0" conaffinity="0" group="1" density="0" />
                <!-- left_rear_abad site geom -->

                <body name='left_rear_hip' pos='-0.08 0.119 0' euler='0 0 0'>
                    <inertial pos="-0.0014 -0.0344 -0.0174" mass="2.22606"
                        fullinertia="0.009416249 0.0090907891 0.0023041271 0.0001223515 -0.0004705786 0.0013313752" />
                    <joint name='HL_hip_joint' type='hinge' axis='0 1 0' limited='true'
                        range='-1.0472 4.1888' damping='1' />
                    <geom type='mesh' mesh='left_rear_hip_mesh_visual' pos='0 0 0' euler='0 0 0'
                        rgba="1 0.5 1 1" />
                    <geom type='mesh' mesh='left_rear_hip_mesh_collision' pos='0 0 0' euler='0 0 0'
                        contype="0" conaffinity="0" group="1" density="0" />
                    <!-- left_rear_hip site geom -->

                    <body name='left_rear_knee' pos='0 0.01 -0.26' euler='0 0 0'>
                        <inertial pos="0.0034 -0.0105 -0.13" mass="0.3261"
                            fullinertia="0.0046064111 0.0046485626 8.17992e-05 -9.9e-09 1.8937e-06 -4.4248e-06" />
                        <joint name='HL_knee_joint' type='hinge' axis='0 1 0' limited='true'
                            range='-2.6965 -0.9163' damping='1' />
                        <geom type='mesh' mesh='left_rear_knee_mesh_visual' pos='0 0 0'
                            euler='0 0 0' rgba="1 0.4 0.4 1" />
                        <geom type='mesh' mesh='left_rear_knee_mesh_collision' pos='0 0 0'
                            euler='0 0 0' contype="0" conaffinity="0" group="1" density="0" />
                        <!-- left_rear_knee site geom -->

                        <body name='HL_foot_link' pos='0.0 -0.01 -0.26149' euler='0 0 0'>
                            <inertial pos="0 0 0" mass="0.000204873572147578"
                                fullinertia="1.09600066619755e-09 1.09600066619755e-09 1.09600066619755e-09 0 0 0" />
                            <geom type='sphere' size='0.035'
                                euler='0 0 0' rgba='0 0.5 1 1' friction="0.7 0.02 0.01" />
                            <geom type='sphere' size='0.035'
                                euler='0 0 0' contype="0" conaffinity="0" group="1" density="0"
                                friction="0.7 0.02 0.01" />
                        </body>
                        <!-- left_rear_knee child body -->
                    </body>
                    <!-- left_rear_hip child body -->
                </body>
                <!-- left_rear_abad child body -->
            </body>

            <body name='right_front_abad' pos='0.2065 -0.065 0.0' euler='-0.0 0.0 -0.0'>
                <inertial pos="0.074261 -0.010662 0.00797" mass="1.748"
                    fullinertia="0.000667447 0.00144482 0.00107312 7.2909e-05 -1.0214e-05 -5.08e-08" />
                <joint name='FR_abd_joint' type='hinge' axis='1 0 0' limited='true'
                    range='-0.80285 0.80285' damping='1' />
                <geom type='mesh' mesh='right_front_abad_mesh_visual' pos='0 0 0' euler='0 0 0'
                    rgba="1 0.4 0.4 1" />
                <geom type='mesh' mesh='right_front_abad_mesh_collision' pos='0 0 0' euler='0 0 0'
                    contype="0" conaffinity="0" group="1" density="0" />
                <!-- right_front_abad site geom -->

                <body name='right_front_hip' pos='0.08 -0.119 0.0' euler='-0.0 0.0 -0.0'>
                    <inertial pos="-0.0014 0.0344 -0.0174" mass="2.22606"
                        fullinertia="0.009416249 0.0090907891 0.0023041271 -0.0001223515 -0.0004705786 -0.0013313752" />
                    <joint name='FR_hip_joint' type='hinge' axis='0 1 0' limited='true'
                        range='-1.0472 4.1888' damping='1' />
                    <geom type='mesh' mesh='right_front_hip_mesh_visual' pos='0 0 0' euler='0 0 0'
                        rgba="1 1 0.4 1" />
                    <geom type='mesh' mesh='right_front_hip_mesh_collision' pos='0 0 0'
                        euler='0 0 0' contype="0" conaffinity="0" group="1" density="0" />
                    <!-- right_front_hip site geom -->

                    <body name='right_front_knee' pos='0.0 -0.01 -0.26' euler='-0.0 0.0 -0.0'>
                        <inertial pos="0.0034 0.0105 -0.13" mass="0.3261"
                            fullinertia="0.0046064111 0.0046485626 8.17992e-05 9.9e-09 1.8937e-06 4.4248e-06" />
                        <joint name='FR_knee_joint' type='hinge' axis='0 1 0'
                            limited='true' range='-2.6965 -0.9163' damping='1' />
                        <geom type='mesh' mesh='right_front_knee_mesh_visual' pos='0 0 0'
                            euler='0 0 0' rgba="0.4 1 0.4 1" />
                        <geom type='mesh' mesh='right_front_knee_mesh_collision' pos='0 0 0'
                            euler='0 0 0' contype="0" conaffinity="0" group="1" density="0" />
                        <!-- right_front_knee site geom -->

                        <body name='FR_foot_link' pos='0.0 0.01 -0.26149'
                            euler='-0.0 0.0 -0.0'>
                            <inertial pos="0.0 -0.0 0.0" mass="0.000204873572147578"
                                fullinertia="1.09600066619755e-09 1.09600066619755e-09 1.09600066619755e-09 -0.0 0.0 -0.0" />
                            <!-- <geom type='sphere' size='0.035' pos='-0.045 -0.0105 -0.012'
                                euler='0 0 0' rgba='0 0.5 1 1' />
                            <geom type='sphere' size='0.035' pos='-0.045 -0.0105 -0.012'
                                euler='0 0 0' contype="0" conaffinity="0" group="1" density="0" /> -->
                            <geom type='sphere' size='0.035'
                                euler='0 0 0' rgba='0 0.5 1 1' friction="0.7 0.02 0.01" />
                            <geom type='sphere' size='0.035'
                                euler='0 0 0' contype="0" conaffinity="0" group="1" density="0"
                                friction="0.7 0.02 0.01" />
                        </body>
                        <!-- right_front_knee child body -->
                    </body>
                    <!-- right_front_hip child body -->
                </body>
                <!-- right_front_abad child body -->
            </body>

            <body name='right_rear_abad' pos='-0.2065 -0.065 0.0' euler='-0.0 0.0 -0.0'>
                <inertial pos="0.074261 -0.010662 0.00797" mass="1.748"
                    fullinertia="0.000667447 0.00144482 0.00107312 -7.2909e-05 1.0214e-05 -5.08e-08" />
                <joint name='HR_abd_joint' type='hinge' axis='1 0 0' limited='true'
                    range='-0.80285 0.80285' damping='1' />
                <geom type='mesh' mesh='right_rear_abad_mesh_visual' pos='0 0 0' euler='0 0 0'
                    rgba="0.8 1.0 0.8 1" />
                <geom type='mesh' mesh='right_rear_abad_mesh_collision' pos='0 0 0' euler='0 0 0'
                    contype="0" conaffinity="0" group="1" density="0" />
                <!-- right_rear_abad site geom -->

                <body name='right_rear_hip' pos='-0.08 -0.119 0.0' euler='-0.0 0.0 -0.0'>
                    <inertial pos="-0.0014 0.0344 -0.0174" mass="2.22606"
                        fullinertia="0.009416249 0.0090907891 0.0023041271 -0.0001223515 -0.0004705786 -0.0013313752" />
                    <joint name='HR_hip_joint' type='hinge' axis='0 1 0' limited='true'
                        range='-1.0472 4.1888' damping='1' />
                    <geom type='mesh' mesh='right_rear_hip_mesh_visual' pos='0 0 0' euler='0 0 0'
                        rgba="1 0.5 1 1" />
                    <geom type='mesh' mesh='right_rear_hip_mesh_collision' pos='0 0 0' euler='0 0 0'
                        contype="0" conaffinity="0" group="1" density="0" />
                    <!-- right_rear_hip site geom -->

                    <body name='right_rear_knee' pos='0.0 -0.01 -0.26' euler='-0.0 0.0 -0.0'>
                        <inertial pos="0.0034 0.0105 -0.13" mass="0.3261"
                            fullinertia="0.0046064111 0.0046485626 8.17992e-05 9.9e-09 1.8937e-06 4.4248e-06" />
                        <joint name='HR_knee_joint' type='hinge' axis='0 1 0' limited='true'
                            range='-2.6965 -0.9163' damping='1' />
                        <geom type='mesh' mesh='right_rear_knee_mesh_visual' pos='0 0 0'
                            euler='0 0 0' rgba="1 0.4 0.4 1" />
                        <geom type='mesh' mesh='right_rear_knee_mesh_collision' pos='0 0 0'
                            euler='0 0 0' contype="0" conaffinity="0" group="1" density="0" />
                        <!-- right_rear_knee site geom -->

                        <body name='HR_foot_link' pos='0.0 0.01 -0.26149'
                            euler='-0.0 0.0 -0.0'>
                            <inertial pos="0.0 -0.0 0.0" mass="0.000204873572147578"
                                fullinertia="1.09600066619755e-09 1.09600066619755e-09 1.09600066619755e-09 -0.0 0.0 -0.0" />
                            <!-- <geom type='sphere' size='0.035' pos='-0.045 -0.0105 -0.012'
                                euler='0 0 0' rgba='0 0.5 1 1' />
                            <geom type='sphere' size='0.035' pos='-0.045 -0.0105 -0.012'
                                euler='0 0 0' contype="0" conaffinity="0" group="1" density="0" /> -->
                            <geom type='sphere' size='0.035'
                                euler='0 0 0' rgba='0 0.5 1 1' friction="0.7 0.02 0.01" />
                            <geom type='sphere' size='0.035'
                                euler='0 0 0' contype="0" conaffinity="0" group="1" density="0"
                                friction="0.7 0.02 0.01" />
                        </body>
                        <!-- right_rear_knee child body -->
                    </body>
                    <!-- right_rear_hip child body -->
                </body>
                <!-- right_rear_abad child body -->
            </body>
            <!-- base_link child body -->
        </body>
        <!-- world child body -->
    </worldbody>

    <actuator>
        <motor name='FL_abd_joint' joint='FL_abd_joint' ctrlrange='-100 100' />
        <motor name='FL_hip_joint' joint='FL_hip_joint' ctrlrange='-100 100' />
        <motor name='FL_knee_joint' joint='FL_knee_joint' ctrlrange='-150 150' />
        <motor name='HL_abd_joint' joint='HL_abd_joint' ctrlrange='-100 100' />
        <motor name='HL_hip_joint' joint='HL_hip_joint' ctrlrange='-100 100' />
        <motor name='HL_knee_joint' joint='HL_knee_joint' ctrlrange='-150 150' />
        <motor name='FR_abd_joint' joint='FR_abd_joint' ctrlrange='-100 100' />
        <motor name='FR_hip_joint' joint='FR_hip_joint' ctrlrange='-100 100' />
        <motor name='FR_knee_joint' joint='FR_knee_joint' ctrlrange='-150 150' />
        <motor name='HR_abd_joint' joint='HR_abd_joint' ctrlrange='-100 100' />
        <motor name='HR_hip_joint' joint='HR_hip_joint' ctrlrange='-100 100' />
        <motor name='HR_knee_joint' joint='HR_knee_joint' ctrlrange='-150 150' />
        <!-- actuator auto generate -->
    </actuator>

    <sensor>
        <framequat name="body-orientation" objtype="site" objname="imu" />
        <gyro name="body-angular-velocity" site="imu" />
        <framepos name="body-linear-pos" objtype="site" objname="imu" />
        <velocimeter name="body-linear-vel" site="imu" />
        <accelerometer name="body-linear-acceleration" site="imu" />
    </sensor>

    <contact>
        <exclude body1="base_link" body2="left_front_abad" />
        <exclude body1="base_link" body2="left_rear_abad" />
        <exclude body1="base_link" body2="right_front_abad" />
        <exclude body1="base_link" body2="right_rear_abad" />
        <exclude body1="left_front_abad" body2="left_front_hip" />
        <exclude body1="left_rear_abad" body2="left_rear_hip" />
        <exclude body1="right_front_abad" body2="right_front_hip" />
        <exclude body1="right_rear_abad" body2="right_rear_hip" />
        <exclude body1="base_link" body2="left_front_hip" />
        <exclude body1="base_link" body2="left_rear_hip" />
        <exclude body1="base_link" body2="right_front_hip" />
        <exclude body1="base_link" body2="right_rear_hip" />
    </contact>

    <keyframe>
        <key name="stand"
            qpos="0 0 0.38 1 0 0 0 0 0.72 -1.44 0 0.72 -1.44 0 0.72 -1.44 0 0.72 -1.44" />
        <key
            qpos='0 0 0.1 1 0 0 0 0.5 1 -2.7 0.5 1 -2.7 -0.5 1 -2.7 -0.5 1 -2.7' />
    </keyframe>
</mujoco>