<mujoco model="galileo_mini">
    <compiler angle="radian" meshdir="../meshes/" autolimits="true" />

    <asset>
        <mesh name="trunk" file="trunk.STL" />
        <mesh name="FR_hip" file="FR_hip.STL" />
        <mesh name="FR_thigh" file="FR_thigh.STL" />
        <mesh name="FR_calf" file="FR_calf.STL" />
        <mesh name="FR_foot" file="FR_foot.STL" />
        <mesh name="RR_hip" file="RR_hip.STL" />
        <mesh name="RR_thigh" file="RR_thigh.STL" />
        <mesh name="RR_calf" file="RR_calf.STL" />
        <mesh name="RR_foot" file="RR_foot.STL" />
        <mesh name="FL_hip" file="FL_hip.STL" />
        <mesh name="FL_thigh" file="FL_thigh.STL" />
        <mesh name="FL_calf" file="FL_calf.STL" />
        <mesh name="FL_foot" file="FL_foot.STL" />
        <mesh name="RL_hip" file="RL_hip.STL" />
        <mesh name="RL_thigh" file="RL_thigh.STL" />
        <mesh name="RL_calf" file="RL_calf.STL" />
        <mesh name="RL_foot" file="RL_foot.STL" />
    </asset>
    <worldbody>
        <body name="trunk" pos="0 0 0.7">
            <inertial pos="0.03738 -0.0065903 0.0057934"
                quat="0.0157641 0.708332 0.0109245 0.705619" mass="20.8"
                diaginertia="0.476858 0.40783 0.131084" />
            <joint name="floating_base_joint" type="free" />
            <geom type="mesh" contype="0" conaffinity="0" group="1" density="0"
                rgba="0.75294 0.75294 0.75294 1" mesh="trunk" />
            <geom type="mesh" rgba="0.75294 0.75294 0.75294 1" mesh="trunk" />
            <site name="site_imu" pos="0 0 0" />

            <body name="FR_hip" pos="0.2015 -0.08 0">
                <inertial pos="0.067568 -0.0091759 -0.00023747"
                    quat="0.461518 0.473275 0.50733 0.552837" mass="2.86"
                    diaginertia="0.00753518 0.00677611 0.00431971" />
                <joint name="FR_hip_joint" pos="0 0 0" axis="1 0 0" range="-0.80285 0.80285" />
                <geom type="mesh" contype="0" conaffinity="0" group="1" density="0"
                    rgba="0.75294 0.75294 0.75294 1" mesh="FR_hip" />
                <geom type="mesh" rgba="0.75294 0.75294 0.75294 1" mesh="FR_hip" />
                <body name="FR_thigh" pos="0.1 -0.10685 0">
                    <inertial pos="-0.0095338 0.026092 -0.067392"
                        quat="0.870643 0.0549937 -0.0729496 0.483357" mass="2.6"
                        diaginertia="0.017109 0.016051 0.00168403" />
                    <joint name="FR_thigh_joint" pos="0 0 0" axis="0 1 0" range="-4.1888 1.0472" />
                    <geom type="mesh" contype="0" conaffinity="0" group="1" density="0"
                        rgba="0.75294 0.75294 0.75294 1" mesh="FR_thigh" />
                    <geom type="mesh" rgba="0.75294 0.75294 0.75294 1" mesh="FR_thigh" />
                    <body name="FR_calf" pos="0 0 -0.26">
                        <inertial pos="0.0178389 -1.57597e-05 -0.0993188"
                            quat="0.703247 0.0575451 0.0571447 0.706305" mass="0.314205"
                            diaginertia="0.00388744 0.0038366 7.88395e-05" />
                        <joint name="FR_calf_joint" pos="0 0 0" axis="0 1 0" range="-2.6965 -0.9163" />
                        <geom type="mesh" contype="0" conaffinity="0" group="1" density="0"
                            rgba="0.75294 0.75294 0.75294 1" mesh="FR_calf" />
                        <geom type="mesh" rgba="0.75294 0.75294 0.75294 1" mesh="FR_calf" />
                        <geom pos="0.032939 0 -0.26149" type="mesh" contype="0" conaffinity="0"
                            group="1" density="0" rgba="1 1 1 1" mesh="FR_foot" />
                        <!-- <geom name="FR_foot" pos="0.032939 0 -0.26149" type="mesh" rgba="1 1 1
                        1" mesh="FR_foot" /> -->
                        <geom name="FR_foot" pos="0.032939 0 -0.26149" type="sphere"
                            rgba="1 1 1 1" size="0.03" friction="0.4 0.02 0.01" />
                        <site name="site_forcesensor1" pos="0.032939 0 -0.26149" />
                    </body>
                </body>
            </body>
            <body name="RR_hip" pos="-0.2015 -0.08 0">
                <inertial pos="-0.067556 -0.0095934 -1.7463e-05"
                    quat="0.554404 0.501113 0.477741 0.461829" mass="2.86"
                    diaginertia="0.00751653 0.00676882 0.00432565" />
                <joint name="RR_hip_joint" pos="0 0 0" axis="1 0 0" range="-0.80285 0.80285" />
                <geom type="mesh" contype="0" conaffinity="0" group="1" density="0"
                    rgba="0.75294 0.75294 0.75294 1" mesh="RR_hip" />
                <geom type="mesh" rgba="0.75294 0.75294 0.75294 1" mesh="RR_hip" />
                <body name="RR_thigh" pos="-0.1 -0.0934 0">
                    <inertial pos="-0.0098055 0.020667 -0.067167"
                        quat="0.935391 0.0800659 -0.0651055 0.338223" mass="2.6"
                        diaginertia="0.0175517 0.0167351 0.0022722" />
                    <joint name="RR_thigh_joint" pos="0 0 0" axis="0 1 0" range="-4.1888 1.0472" />
                    <geom type="mesh" contype="0" conaffinity="0" group="1" density="0"
                        rgba="0.75294 0.75294 0.75294 1" mesh="RR_thigh" />
                    <geom type="mesh" rgba="0.75294 0.75294 0.75294 1" mesh="RR_thigh" />
                    <body name="RR_calf" pos="0 0 -0.26">
                        <inertial pos="0.0178389 -1.57597e-05 -0.0993188"
                            quat="0.703247 0.0575451 0.0571447 0.706305" mass="0.314205"
                            diaginertia="0.00388744 0.0038366 7.88395e-05" />
                        <joint name="RR_calf_joint" pos="0 0 0" axis="0 1 0" range="-2.6965 -0.9163" />
                        <geom type="mesh" contype="0" conaffinity="0" group="1" density="0"
                            rgba="0.75294 0.75294 0.75294 1" mesh="RR_calf" />
                        <geom type="mesh" rgba="0.75294 0.75294 0.75294 1" mesh="RR_calf" />
                        <geom pos="0.032939 0 -0.26149" type="mesh" contype="0" conaffinity="0"
                            group="1" density="0" rgba="1 1 1 1" mesh="RR_foot" />
                        <!-- <geom name="RR_foot" pos="0.032939 0 -0.26149" type="mesh" rgba="1 1 1
                        1" mesh="RR_foot" /> -->
                        <geom name="RR_foot" pos="0.032939 0 -0.26149" type="sphere"
                            rgba="1 1 1 1" size="0.03" friction="0.4 0.02 0.01" />
                        <site name="site_forcesensor2" pos="0.032939 0 -0.26149" />
                    </body>
                </body>
            </body>
            <body name="FL_hip" pos="0.2015 0.08 0">
                <inertial pos="0.067568 0.0095934 1.3738e-05"
                    quat="0.500634 0.554466 0.463464 0.476585" mass="2.86"
                    diaginertia="0.00752069 0.00677878 0.00432153" />
                <joint name="FL_hip_joint" pos="0 0 0" axis="1 0 0" range="-0.80285 0.80285" />
                <geom type="mesh" contype="0" conaffinity="0" group="1" density="0"
                    rgba="0.75294 0.75294 0.75294 1" mesh="FL_hip" />
                <geom type="mesh" rgba="0.75294 0.75294 0.75294 1" mesh="FL_hip" />
                <body name="FL_thigh" pos="0.1 0.1065 0">
                    <inertial pos="-0.0090988 -0.0065295 -0.0688"
                        quat="0.419807 -0.0627305 0.0522402 0.903935" mass="2.6"
                        diaginertia="0.017487 0.0165271 0.00167088" />
                    <joint name="FL_thigh_joint" pos="0 0 0" axis="0 1 0" range="-4.1888 1.0472" />
                    <geom type="mesh" contype="0" conaffinity="0" group="1" density="0"
                        rgba="0.75294 0.75294 0.75294 1" mesh="FL_thigh" />
                    <geom type="mesh" rgba="0.75294 0.75294 0.75294 1" mesh="FL_thigh" />
                    <body name="FL_calf" pos="0 0 -0.26">
                        <inertial pos="0.0178389 -1.57597e-05 -0.0993188"
                            quat="0.703247 0.0575451 0.0571447 0.706305" mass="0.314205"
                            diaginertia="0.00388744 0.0038366 7.88395e-05" />
                        <joint name="FL_calf_joint" pos="0 0 0" axis="0 1 0" range="-2.6965 -0.9163" />
                        <geom type="mesh" contype="0" conaffinity="0" group="1" density="0"
                            rgba="0.75294 0.75294 0.75294 1" mesh="FL_calf" />
                        <geom type="mesh" rgba="0.75294 0.75294 0.75294 1" mesh="FL_calf" />
                        <geom pos="0.032939 0 -0.26149" type="mesh" contype="0" conaffinity="0"
                            group="1" density="0" rgba="1 1 1 1" mesh="FL_foot" />
                        <!-- <geom name="FL_foot" pos="0.032939 0 -0.26149" type="mesh" rgba="1 1 1
                        1" mesh="FL_foot" /> -->
                        <geom name="FL_foot" pos="0.0329385 0 -0.26149" type="sphere"
                            rgba="1 1 1 1" size="0.03" friction="0.4 0.02 0.01" />
                        <site name="site_forcesensor3" pos="0.032939 0 -0.26149" />
                    </body>
                </body>
            </body>
            <body name="RL_hip" pos="-0.2015 0.08 0">
                <inertial pos="-0.06741 0.0095934 7.3103e-05"
                    quat="0.554404 0.501113 0.477741 0.461829" mass="2.86"
                    diaginertia="0.00751653 0.00676882 0.00432565" />
                <joint name="RL_hip_joint" pos="0 0 0" axis="1 0 0" range="-0.80285 0.80285" />
                <geom type="mesh" contype="0" conaffinity="0" group="1" density="0"
                    rgba="0.75294 0.75294 0.75294 1" mesh="RL_hip" />
                <geom type="mesh" rgba="0.75294 0.75294 0.75294 1" mesh="RL_hip" />
                <body name="RL_thigh" pos="-0.1 0.1065 0">
                    <inertial pos="-0.0090357 -0.0065295 -0.0688"
                        quat="0.419807 -0.0627305 0.0522402 0.903935" mass="2.6"
                        diaginertia="0.017487 0.0165271 0.00167088" />
                    <joint name="RL_thigh_joint" pos="0 0 0" axis="0 1 0" range="-4.1888 1.0472" />
                    <geom type="mesh" contype="0" conaffinity="0" group="1" density="0"
                        rgba="0.75294 0.75294 0.75294 1" mesh="RL_thigh" />
                    <geom type="mesh" rgba="0.75294 0.75294 0.75294 1" mesh="RL_thigh" />
                    <body name="RL_calf" pos="6.3209e-05 0 -0.26">
                        <inertial pos="0.0178389 -1.57597e-05 -0.0993188"
                            quat="0.703247 0.0575451 0.0571447 0.706305" mass="0.314205"
                            diaginertia="0.00388744 0.0038366 7.88395e-05" />
                        <joint name="RL_calf_joint" pos="0 0 0" axis="0 1 0" range="-2.6965 -0.9163" />
                        <geom type="mesh" contype="0" conaffinity="0" group="1" density="0"
                            rgba="0.75294 0.75294 0.75294 1" mesh="RL_calf" />
                        <geom type="mesh" rgba="0.75294 0.75294 0.75294 1" mesh="RL_calf" />
                        <geom pos="0.0329385 0 -0.261493" type="mesh" contype="0" conaffinity="0"
                            group="1" density="0" rgba="1 1 1 1" mesh="RL_foot" />
                        <!-- <geom name="RL_foot" pos="0.0329385 0 -0.261493" type="mesh" rgba="1 1
                        1 1" mesh="RL_foot" /> -->
                        <geom name="RL_foot" pos="0.0329385 0 -0.261493" type="sphere"
                            rgba="1 1 1 1" size="0.03" friction="0.4 0.02 0.01" />
                        <site name="site_forcesensor4" pos="0.032939 0 -0.26149" />
                    </body>
                </body>
            </body>
        </body>
    </worldbody>
    <actuator>
        <motor name="FR_hip_joint" joint="FR_hip_joint" gear="1" ctrllimited="true"
            ctrlrange="-180 180" />
        <motor name="RR_hip_joint" joint="RR_hip_joint" gear="1" ctrllimited="true"
            ctrlrange="-180 180" />
        <motor name="FL_hip_joint" joint="FL_hip_joint" gear="1" ctrllimited="true"
            ctrlrange="-180 180" />
        <motor name="RL_hip_joint" joint="RL_hip_joint" gear="1" ctrllimited="true"
            ctrlrange="-180 180" />

        <motor name="FR_thigh_joint" joint="FR_thigh_joint" gear="1" ctrllimited="true"
            ctrlrange="-180 180" />
        <motor name="RR_thigh_joint" joint="RR_thigh_joint" gear="1" ctrllimited="true"
            ctrlrange="-180 180" />
        <motor name="FL_thigh_joint" joint="FL_thigh_joint" gear="1" ctrllimited="true"
            ctrlrange="-180 180" />
        <motor name="RL_thigh_joint" joint="RL_thigh_joint" gear="1" ctrllimited="true"
            ctrlrange="-180 180" />

        <motor name="FR_calf_joint" joint="FR_calf_joint" gear="1" ctrllimited="true"
            ctrlrange="-180 180" />
        <motor name="RR_calf_joint" joint="RR_calf_joint" gear="1" ctrllimited="true"
            ctrlrange="-180 180" />
        <motor name="FL_calf_joint" joint="FL_calf_joint" gear="1" ctrllimited="true"
            ctrlrange="-180 180" />
        <motor name="RL_calf_joint" joint="RL_calf_joint" gear="1" ctrllimited="true"
            ctrlrange="-180 180" />
    </actuator>
    <sensor>
        <force name="forcesensor1" site="site_forcesensor1" cutoff="5000.0" />
        <force name="forcesensor2" site="site_forcesensor2" cutoff="5000.0" />
        <force name="forcesensor3" site="site_forcesensor3" cutoff="5000.0" />
        <force name="forcesensor4" site="site_forcesensor4" cutoff="5000.0" />

        <framequat name="imu_quat" objtype="site" objname="site_imu" />
        <accelerometer name="imu_acc" site="site_imu" />
        <gyro name="imu_gyro" site="site_imu" />
    </sensor>

    <contact>
        <exclude body1="trunk" body2="FR_hip" />
        <exclude body1="trunk" body2="RR_hip" />
        <exclude body1="trunk" body2="FL_hip" />
        <exclude body1="trunk" body2="RL_hip" />
        <exclude body1="trunk" body2="FR_thigh" />
        <exclude body1="trunk" body2="RR_thigh" />
        <exclude body1="trunk" body2="FL_thigh" />
        <exclude body1="trunk" body2="RL_thigh" />
    </contact>

    <keyframe>
        <key name="stand"
            qpos="0 0 0.38 1 0 0 0 0 0.72 -1.44 0 0.72 -1.44 0 0.72 -1.44 0 0.72 -1.44" />
        <key name="down"
            qpos="0 0 0.38 1 0 0 0 -0.5 1.05 -2.46 -0.5 1.05 -2.46 0.5 1.05 -2.46 0.5 1.05 -2.46" />
    </keyframe>

</mujoco>