<?xml version="1.0" encoding="utf-8"?>
<!-- This URDF was automatically created by SolidWorks to URDF Exporter! Originally created by
Stephen Brawner (brawner@gmail.com) 
     Commit Version: 1.6.0-1-g15f4949  Build Version: 1.6.7594.29634
     For more information, please see http://wiki.ros.org/sw_urdf_exporter -->
<robot name="bqr3">
  <link name="world" />
  <joint name="floating_base_joint" type="fixed">
    <origin xyz="0 0 0" rpy="0 0 0" />
    <parent link="world" />
    <child link="base_link" />
  </joint>
  <link name="base_link">
    <inertial>
      <origin
        xyz="-0.000092 0.001447 -0.042478"
        rpy="0 0 0" />
      <mass
        value="26.5" />
      <inertia
        ixx="0.259494841"
        ixy="-4.1227E-05"
        ixz="1.93862E-04"
        iyy="0.859939262"
        iyz="-2.040130E-03"
        izz="0.945567440" />
    </inertial>
    <visual>
      <origin
        xyz="0 0 0"
        rpy="0 0 0" />
      <geometry>
        <mesh
          filename="package://bqr3_description/meshes/base_link.STL" />
      </geometry>
      <material
        name="">
        <color
          rgba="0.79216 0.81961 0.93333 1" />
      </material>
    </visual>
    <collision>
      <origin
        xyz="0 0 0"
        rpy="0 0 0" />
      <geometry>
        <mesh
          filename="package://bqr3_description/meshes/base_link.STL" />
      </geometry>
    </collision>
  </link>
  <link name="FR_hip">
    <inertial>
      <origin
        xyz="0.050570 0.046892 1.0E-06"
        rpy="0 0 0" />
      <mass
        value="1.656" />
      <inertia
        ixx="0.002476692"
        ixy="4.00827E-04"
        ixz="3.0E-09"
        iyy="2.206021E-03"
        iyz="-5.9E-08"
        izz="2.653852E-03" />
    </inertial>
    <visual>
      <origin
        xyz="0 0 0"
        rpy="0 0 0" />
      <geometry>
        <mesh
          filename="package://bqr3_description/meshes/FR_hip.STL" />
      </geometry>
      <material
        name="">
        <color
          rgba="0.89804 0.91765 0.92941 1" />
      </material>
    </visual>
    <collision>
      <origin
        xyz="0 0 0"
        rpy="0 0 0" />
      <geometry>
        <mesh
          filename="package://bqr3_description/meshes/FR_hip.STL" />
      </geometry>
    </collision>
  </link>
  <joint name="FR_hip_joint" type="revolute">
    <origin
      xyz="0.244 -0.115 0"
      rpy="0 0 0" />
    <parent
      link="base_link" />
    <child
      link="FR_hip" />
    <axis
      xyz="1 0 0" />
    <limit
      effort="0"
      velocity="0" />
  </joint>
  <link name="FR_thigh">
    <inertial>
      <origin
        xyz="-0.00063 -0.0201 -0.15827"
        rpy="0 0 0" />
      <mass
        value="1.337" />
      <inertia
        ixx="0.018816808"
        ixy="-3.29929E-05"
        ixz="0.000792"
        iyy="0.018864419"
        iyz="0.000185"
        izz="0.000837451" />
    </inertial>
    <visual>
      <origin
        xyz="0 0 0"
        rpy="0 0 0" />
      <geometry>
        <mesh
          filename="package://bqr3_description/meshes/FR_thigh.STL" />
      </geometry>
      <material
        name="">
        <color
          rgba="0.79216 0.81961 0.93333 1" />
      </material>
    </visual>
    <collision>
      <origin
        xyz="0 0 0"
        rpy="0 0 0" />
      <geometry>
        <mesh
          filename="package://bqr3_description/meshes/FR_thigh.STL" />
      </geometry>
    </collision>
  </link>
  <joint name="FR_thigh_joint" type="revolute">
    <origin
      xyz="0.056 0.018587 0"
      rpy="0 0 0" />
    <parent
      link="FR_hip" />
    <child
      link="FR_thigh" />
    <axis
      xyz="0 -1 0" />
    <limit
      effort="0"
      velocity="0" />
  </joint>
  <link name="FR_calf">
    <inertial>
      <origin
        xyz="-0.00517 0 -0.12521"
        rpy="0 0 0" />
      <mass
        value="0.6489" />
      <inertia
        ixx="0.006478288"
        ixy="2.4E-10"
        ixz="-0.00013"
        iyy="0.006528945"
        iyz="-1.015E-08"
        izz="0.00013568" />
    </inertial>
    <visual>
      <origin
        xyz="0 0 0"
        rpy="0 0 0" />
      <geometry>
        <mesh
          filename="package://bqr3_description/meshes/FR_calf.STL" />
      </geometry>
      <material
        name="">
        <color
          rgba="0.898039215686275 0.917647058823529 0.929411764705882 1" />
      </material>
    </visual>
    <collision>
      <origin
        xyz="0 0 0"
        rpy="0 0 0" />
      <geometry>
        <mesh
          filename="package://bqr3_description/meshes/FR_calf.STL" />
      </geometry>
    </collision>
  </link>
  <joint name="FR_calf_joint" type="revolute">
    <origin
      xyz="0 -0.10009 -0.36"
      rpy="0 0 0" />
    <parent
      link="FR_thigh" />
    <child
      link="FR_calf" />
    <axis
      xyz="0 -1 0" />
    <limit
      effort="0"
      velocity="0" />
  </joint>
  <link name="FR_foot">
    <inertial>
      <origin
        xyz="0.0011791 -0.00030084 -0.0024379"
        rpy="0 0 0" />
      <mass
        value="0.10321" />
      <inertia
        ixx="2.9572E-05"
        ixy="3.6317E-09"
        ixz="6.7484E-07"
        iyy="3.5401E-05"
        iyz="-9.1467E-09"
        izz="2.9167E-05" />
    </inertial>
    <visual>
      <origin
        xyz="0 0 0"
        rpy="0 0 0" />
      <geometry>
        <mesh
          filename="package://bqr3_description/meshes/FR_foot.STL" />
      </geometry>
      <material
        name="">
        <color
          rgba="1 1 1 1" />
      </material>
    </visual>
    <collision>
      <origin
        xyz="0 0 0"
        rpy="0 0 0" />
      <geometry>
        <mesh
          filename="package://bqr3_description/meshes/FR_foot.STL" />
      </geometry>
    </collision>
  </link>
  <joint name="FR_foot_joint" type="fixed">
    <origin
      xyz="-0.00054829 0 -0.36"
      rpy="0 0 0" />
    <parent
      link="FR_calf" />
    <child
      link="FR_foot" />
    <axis
      xyz="0 0 0" />
    <limit
      effort="0"
      velocity="0" />
  </joint>
  <link name="RR_hip">
    <inertial>
      <origin
        xyz="-0.050570 0.046982 -1.0E-06"
        rpy="0 0 0" />
      <mass
        value="1.656" />
      <inertia
        ixx="0.002476692"
        ixy="-4.00827E-04"
        ixz="3.0E-09"
        iyy="2.206021E-03"
        iyz="5.9E-08"
        izz="2.653852E-03" />
    </inertial>
    <visual>
      <origin
        xyz="0 0 0"
        rpy="0 0 0" />
      <geometry>
        <mesh
          filename="package://bqr3_description/meshes/RR_hip.STL" />
      </geometry>
      <material
        name="">
        <color
          rgba="0.89804 0.91765 0.92941 1" />
      </material>
    </visual>
    <collision>
      <origin
        xyz="0 0 0"
        rpy="0 0 0" />
      <geometry>
        <mesh
          filename="package://bqr3_description/meshes/RR_hip.STL" />
      </geometry>
    </collision>
  </link>
  <joint name="RR_hip_joint" type="revolute">
    <origin
      xyz="-0.244 -0.115 0"
      rpy="0 0 0" />
    <parent
      link="base_link" />
    <child
      link="RR_hip" />
    <axis
      xyz="1 0 0" />
    <limit
      effort="0"
      velocity="0" />
  </joint>
  <link name="RR_thigh">
    <inertial>
      <origin
        xyz="-0.00063 -0.0201 -0.15827"
        rpy="0 0 0" />
      <mass
        value="1.337" />
      <inertia
        ixx="0.018816808"
        ixy="-3.29929E-05"
        ixz="0.000792"
        iyy="0.018864419"
        iyz="0.000185"
        izz="0.000837451" />
    </inertial>
    <visual>
      <origin
        xyz="0 0 0"
        rpy="0 0 0" />
      <geometry>
        <mesh
          filename="package://bqr3_description/meshes/RR_thigh.STL" />
      </geometry>
      <material
        name="">
        <color
          rgba="0.79216 0.81961 0.93333 1" />
      </material>
    </visual>
    <collision>
      <origin
        xyz="0 0 0"
        rpy="0 0 0" />
      <geometry>
        <mesh
          filename="package://bqr3_description/meshes/RR_thigh.STL" />
      </geometry>
    </collision>
  </link>
  <joint name="RR_thigh_joint" type="revolute">
    <origin
      xyz="-0.056 0.018587 0"
      rpy="0 0 0" />
    <parent
      link="RR_hip" />
    <child
      link="RR_thigh" />
    <axis
      xyz="0 -1 0" />
    <limit
      effort="0"
      velocity="0" />
  </joint>
  <link name="RR_calf">
    <inertial>
      <origin
        xyz="-0.00517 0 -0.12521"
        rpy="0 0 0" />
      <mass
        value="0.6489" />
      <inertia
        ixx="0.006478288"
        ixy="2.4E-10"
        ixz="-0.00013"
        iyy="0.006528945"
        iyz="-1.015E-08"
        izz="0.00013568" />
    </inertial>
    <visual>
      <origin
        xyz="0 0 0"
        rpy="0 0 0" />
      <geometry>
        <mesh
          filename="package://bqr3_description/meshes/RR_calf.STL" />
      </geometry>
      <material
        name="">
        <color
          rgba="0.89804 0.91765 0.92941 1" />
      </material>
    </visual>
    <collision>
      <origin
        xyz="0 0 0"
        rpy="0 0 0" />
      <geometry>
        <mesh
          filename="package://bqr3_description/meshes/RR_calf.STL" />
      </geometry>
    </collision>
  </link>
  <joint name="RR_calf_joint" type="revolute">
    <origin
      xyz="0 -0.10009 -0.36"
      rpy="0 0 0" />
    <parent
      link="RR_thigh" />
    <child
      link="RR_calf" />
    <axis
      xyz="0 -1 0" />
    <limit
      effort="0"
      velocity="0" />
  </joint>
  <link name="RR_foot">
    <inertial>
      <origin
        xyz="0.0011791 -0.00030085 -0.0024379"
        rpy="0 0 0" />
      <mass
        value="0.10321" />
      <inertia
        ixx="2.9572E-05"
        ixy="3.6261E-09"
        ixz="6.7484E-07"
        iyy="3.5401E-05"
        iyz="-9.1442E-09"
        izz="2.9167E-05" />
    </inertial>
    <visual>
      <origin
        xyz="0 0 0"
        rpy="0 0 0" />
      <geometry>
        <mesh
          filename="package://bqr3_description/meshes/RR_foot.STL" />
      </geometry>
      <material
        name="">
        <color
          rgba="1 1 1 1" />
      </material>
    </visual>
    <collision>
      <origin
        xyz="0 0 0"
        rpy="0 0 0" />
      <geometry>
        <mesh
          filename="package://bqr3_description/meshes/RR_foot.STL" />
      </geometry>
    </collision>
  </link>
  <joint name="RR_foot_joint" type="fixed">
    <origin
      xyz="-0.00054828 0 -0.36"
      rpy="0 0 0" />
    <parent
      link="RR_calf" />
    <child
      link="RR_foot" />
    <axis
      xyz="0 0 0" />
    <limit
      effort="0"
      velocity="0" />
  </joint>
  <link name="FL_hip">
    <inertial>
      <origin
        xyz="0.050570 -0.046982 -1.0E-06"
        rpy="0 0 0" />
      <mass
        value="1.656" />
      <inertia
        ixx="0.002476692"
        ixy="-4.00827E-04"
        ixz="-3.0E-09"
        iyy="2.206021E-03"
        iyz="-5.9E-08"
        izz="2.653852E-03" />
    </inertial>
    <visual>
      <origin
        xyz="0 0 0"
        rpy="0 0 0" />
      <geometry>
        <mesh
          filename="package://bqr3_description/meshes/FL_hip.STL" />
      </geometry>
      <material
        name="">
        <color
          rgba="0.89804 0.91765 0.92941 1" />
      </material>
    </visual>
    <collision>
      <origin
        xyz="0 0 0"
        rpy="0 0 0" />
      <geometry>
        <mesh
          filename="package://bqr3_description/meshes/FL_hip.STL" />
      </geometry>
    </collision>
  </link>
  <joint name="FL_hip_joint" type="revolute">
    <origin
      xyz="0.244 0.115 0"
      rpy="0 0 0" />
    <parent
      link="base_link" />
    <child
      link="FL_hip" />
    <axis
      xyz="1 0 0" />
    <limit
      effort="0"
      velocity="0" />
  </joint>
  <link name="FL_thigh">
    <inertial>
      <origin
        xyz="-0.00063 0.0201 -0.15827"
        rpy="0 0 0" />
      <mass
        value="1.337" />
      <inertia
        ixx="0.018816835"
        ixy="-3.29964E-05"
        ixz="0.000792"
        iyy="0.018864405"
        iyz="0.000185353"
        izz="0.000837413" />
    </inertial>
    <visual>
      <origin
        xyz="0 0 0"
        rpy="0 0 0" />
      <geometry>
        <mesh
          filename="package://bqr3_description/meshes/FL_thigh.STL" />
      </geometry>
      <material
        name="">
        <color
          rgba="0.79216 0.81961 0.93333 1" />
      </material>
    </visual>
    <collision>
      <origin
        xyz="0 0 0"
        rpy="0 0 0" />
      <geometry>
        <mesh
          filename="package://bqr3_description/meshes/FL_thigh.STL" />
      </geometry>
    </collision>
  </link>
  <joint name="FL_thigh_joint" type="revolute">
    <origin
      xyz="0.056 -0.018587 0"
      rpy="0 0 0" />
    <parent
      link="FL_hip" />
    <child
      link="FL_thigh" />
    <axis
      xyz="0 -1 0" />
    <limit
      effort="0"
      velocity="0" />
  </joint>
  <link name="FL_calf">
    <inertial>
      <origin
        xyz="-0.00517 0 -0.12521"
        rpy="0 0 0" />
      <mass
        value="0.6489" />
      <inertia
        ixx="0.006478288"
        ixy="2.4E-10"
        ixz="-0.00013"
        iyy="0.006528945"
        iyz="-1.015E-08"
        izz="0.00013568" />
    </inertial>
    <visual>
      <origin
        xyz="0 0 0"
        rpy="0 0 0" />
      <geometry>
        <mesh
          filename="package://bqr3_description/meshes/FL_calf.STL" />
      </geometry>
      <material
        name="">
        <color
          rgba="0.89804 0.91765 0.92941 1" />
      </material>
    </visual>
    <collision>
      <origin
        xyz="0 0 0"
        rpy="0 0 0" />
      <geometry>
        <mesh
          filename="package://bqr3_description/meshes/FL_calf.STL" />
      </geometry>
    </collision>
  </link>
  <joint name="FL_calf_joint" type="revolute">
    <origin
      xyz="0 0.10009 -0.36"
      rpy="0 0 0" />
    <parent
      link="FL_thigh" />
    <child
      link="FL_calf" />
    <axis
      xyz="0 -1 0" />
    <limit
      effort="0"
      velocity="0" />
  </joint>
  <link name="FL_foot">
    <inertial>
      <origin
        xyz="0.0011791 9.9156E-05 -0.0024379"
        rpy="0 0 0" />
      <mass
        value="0.10321" />
      <inertia
        ixx="2.9572E-05"
        ixy="3.6295E-09"
        ixz="6.7484E-07"
        iyy="3.5401E-05"
        iyz="-9.1457E-09"
        izz="2.9167E-05" />
    </inertial>
    <visual>
      <origin
        xyz="0 0 0"
        rpy="0 0 0" />
      <geometry>
        <mesh
          filename="package://bqr3_description/meshes/FL_foot.STL" />
      </geometry>
      <material
        name="">
        <color
          rgba="1 1 1 1" />
      </material>
    </visual>
    <collision>
      <origin
        xyz="0 0 0"
        rpy="0 0 0" />
      <geometry>
        <mesh
          filename="package://bqr3_description/meshes/FL_foot.STL" />
      </geometry>
    </collision>
  </link>
  <joint name="FL_foot_joint" type="fixed">
    <origin
      xyz="-0.00054828 0 -0.36"
      rpy="0 0 0" />
    <parent
      link="FL_calf" />
    <child
      link="FL_foot" />
    <axis
      xyz="0 0 0" />
    <limit
      effort="0"
      velocity="0" />
  </joint>
  <link name="RL_hip">
    <inertial>
      <origin
        xyz="-0.050570 -0.046982 1.0E-06"
        rpy="0 0 0" />
      <mass
        value="1.656" />
      <inertia
        ixx="0.002476692"
        ixy="4.00827E-04"
        ixz="-3.0E-09"
        iyy="2.206021E-03"
        iyz="5.9E-08"
        izz="2.653852E-03" />
    </inertial>
    <visual>
      <origin
        xyz="0 0 0"
        rpy="0 0 0" />
      <geometry>
        <mesh
          filename="package://bqr3_description/meshes/RL_hip.STL" />
      </geometry>
      <material
        name="">
        <color
          rgba="0.89804 0.91765 0.92941 1" />
      </material>
    </visual>
    <collision>
      <origin
        xyz="0 0 0"
        rpy="0 0 0" />
      <geometry>
        <mesh
          filename="package://bqr3_description/meshes/RL_hip.STL" />
      </geometry>
    </collision>
  </link>
  <joint name="RL_hip_joint" type="revolute">
    <origin
      xyz="-0.244 0.115 0"
      rpy="0 0 0" />
    <parent
      link="base_link" />
    <child
      link="RL_hip" />
    <axis
      xyz="1 0 0" />
    <limit
      effort="0"
      velocity="0" />
  </joint>
  <link name="RL_thigh">
    <inertial>
      <origin
        xyz="-0.00063 0.0201 -0.15827"
        rpy="0 0 0" />
      <mass
        value="1.337" />
      <inertia
        ixx="0.018816835"
        ixy="-3.29964E-05"
        ixz="0.000792"
        iyy="0.018864405"
        iyz="0.000185353"
        izz="0.000837413" />
    </inertial>
    <visual>
      <origin
        xyz="0 0 0"
        rpy="0 0 0" />
      <geometry>
        <mesh
          filename="package://bqr3_description/meshes/RL_thigh.STL" />
      </geometry>
      <material
        name="">
        <color
          rgba="0.89804 0.91765 0.92941 1" />
      </material>
    </visual>
    <collision>
      <origin
        xyz="0 0 0"
        rpy="0 0 0" />
      <geometry>
        <mesh
          filename="package://bqr3_description/meshes/RL_thigh.STL" />
      </geometry>
    </collision>
  </link>
  <joint name="RL_thigh_joint" type="revolute">
    <origin
      xyz="-0.056 -0.018588 0"
      rpy="0 0 0" />
    <parent
      link="RL_hip" />
    <child
      link="RL_thigh" />
    <axis
      xyz="0 -1 0" />
    <limit
      effort="0"
      velocity="0" />
  </joint>
  <link name="RL_calf">
    <inertial>
      <origin
        xyz="-0.00517 0 -0.12521"
        rpy="0 0 0" />
      <mass
        value="0.6489" />
      <inertia
        ixx="0.006478288"
        ixy="2.4E-10"
        ixz="-0.00013"
        iyy="0.006528945"
        iyz="-1.015E-08"
        izz="0.00013568" />
    </inertial>
    <visual>
      <origin
        xyz="0 0 0"
        rpy="0 0 0" />
      <geometry>
        <mesh
          filename="package://bqr3_description/meshes/RL_calf.STL" />
      </geometry>
      <material
        name="">
        <color
          rgba="0.89804 0.91765 0.92941 1" />
      </material>
    </visual>
    <collision>
      <origin
        xyz="0 0 0"
        rpy="0 0 0" />
      <geometry>
        <mesh
          filename="package://bqr3_description/meshes/RL_calf.STL" />
      </geometry>
    </collision>
  </link>
  <joint name="RL_calf_joint" type="revolute">
    <origin
      xyz="0 0.10009 -0.36"
      rpy="0 0 0" />
    <parent
      link="RL_thigh" />
    <child
      link="RL_calf" />
    <axis
      xyz="0 -1 0" />
    <limit
      effort="0"
      velocity="0" />
  </joint>
  <link name="RL_foot">
    <inertial>
      <origin
        xyz="0.0011791 0.00049916 -0.0024379"
        rpy="0 0 0" />
      <mass
        value="0.10321" />
      <inertia
        ixx="2.9572E-05"
        ixy="3.6351E-09"
        ixz="6.7483E-07"
        iyy="3.5401E-05"
        iyz="-9.1482E-09"
        izz="2.9167E-05" />
    </inertial>
    <visual>
      <origin
        xyz="0 0 0"
        rpy="0 0 0" />
      <geometry>
        <mesh
          filename="package://bqr3_description/meshes/RL_foot.STL" />
      </geometry>
      <material
        name="">
        <color
          rgba="1 1 1 1" />
      </material>
    </visual>
    <collision>
      <origin
        xyz="0 0 0"
        rpy="0 0 0" />
      <geometry>
        <mesh
          filename="package://bqr3_description/meshes/RL_foot.STL" />
      </geometry>
    </collision>
  </link>
  <joint name="RL_foot_joint" type="fixed">
    <origin
      xyz="-0.00054828 0 -0.36"
      rpy="0 0 0" />
    <parent
      link="RL_calf" />
    <child
      link="RL_foot" />
    <axis
      xyz="0 0 0" />
    <limit
      effort="0"
      velocity="0" />
  </joint>
</robot>