<mujoco model="quadruped">
    <compiler angle="radian" meshdir="../meshes/" autolimits="true" />
    <option timestep="0.001" integrator="RK4">
        <!--		<flag sensornoise="enable" />-->
    </option>

    <visual>
        <map force="0.1" zfar="30" />
        <rgba haze="0.15 0.25 0.35 1" />
        <global offwidth="2560" offheight="1440" elevation="-20" azimuth="120" />
    </visual>

    <asset>
        <texture type="skybox" builtin="gradient" rgb1=".3 .5 .7" rgb2="0 0 0" width="32"
            height="512" />
        <texture name="body" type="cube" builtin="flat" mark="cross" width="127" height="1278"
            rgb1="0.8 0.6 0.4"
            rgb2="0.8 0.6 0.4" markrgb="1 1 1" random="0.01" />
        <material name="body" texture="body" texuniform="true" rgba="0.8 0.6 .4 1" />
        <texture name="grid" type="2d" builtin="checker" width="512" height="512" rgb1=".1 .2 .3"
            rgb2=".2 .3 .4" />
        <material name="grid" texture="grid" texrepeat="1 1" texuniform="true" reflectance=".2" />
    </asset>

    <asset>
        <mesh name="base_link" file="base_link.STL" />
        <mesh name="FR_hip" file="FR_hip.STL" />
        <mesh name="FR_thigh" file="FR_thigh.STL" />
        <mesh name="FR_calf" file="FR_calf.STL" />
        <mesh name="FR_foot" file="FR_foot.STL" />
        <mesh name="RR_hip" file="RR_hip.STL" />
        <mesh name="RR_thigh" file="RR_thigh.STL" />
        <mesh name="RR_calf" file="RR_calf.STL" />
        <mesh name="RR_foot" file="RR_foot.STL" />
        <mesh name="FL_hip" file="FL_hip.STL" />
        <mesh name="FL_thigh" file="FL_thigh.STL" />
        <mesh name="FL_calf" file="FL_calf.STL" />
        <mesh name="FL_foot" file="FL_foot.STL" />
        <mesh name="RL_hip" file="RL_hip.STL" />
        <mesh name="RL_thigh" file="RL_thigh.STL" />
        <mesh name="RL_calf" file="RL_calf.STL" />
        <mesh name="RL_foot" file="RL_foot.STL" />
    </asset>
    <worldbody>
        <light diffuse=".5 .5 .5" pos="0 0 3" dir="0 0 -1" />
        <geom name="floor" type="plane" size="0 0 0.05" material="grid" />
        <body name="base_link" pos="0.0 0.0 0.9">
            <inertial pos="-9.2e-05 0.001447 -0.042478"
                quat="-0.00843975 0.707157 -0.00839426 0.706957" mass="35"
                diaginertia="0.945616 0.859891 0.259495" />
            <joint name="floating_base_joint" type="free" />
            <geom type="mesh" contype="0" conaffinity="0" group="1" density="0"
                rgba="0.79216 0.81961 0.93333 1"
                mesh="base_link" />
            <geom type="mesh" rgba="0.79216 0.81961 0.93333 1" mesh="base_link" />
            <site name="site_imu" pos="0 0 0" />

            <body name="FR_hip" pos="0.244 -0.115 0">
                <inertial pos="0.05057 0.046892 1e-06" quat="0.673131 0.673113 0.216685 0.216475"
                    mass="1.656"
                    diaginertia="0.00276441 0.00265385 0.0019183" />
                <joint name="FR_hip_joint" pos="0 0 0" axis="1 0 0" />
                <geom type="mesh" contype="0" conaffinity="0" group="1" density="0"
                    rgba="0.89804 0.91765 0.92941 1"
                    mesh="FR_hip" />
                <geom type="mesh" rgba="0.89804 0.91765 0.92941 1" mesh="FR_hip" />
                <body name="FR_thigh" pos="0.056 0.018587 0">
                    <inertial pos="-0.00063 -0.0201 -0.15827"
                        quat="0.447929 -0.0173336 -0.0144553 0.893784"
                        mass="1.337" diaginertia="0.0188849 0.0188331 0.00080071" />
                    <joint name="FR_thigh_joint" pos="0 0 0" axis="0 -1 0" />
                    <geom type="mesh" contype="0" conaffinity="0" group="1" density="0"
                        rgba="0.79216 0.81961 0.93333 1"
                        mesh="FR_thigh" />
                    <geom type="mesh" rgba="0.79216 0.81961 0.93333 1" mesh="FR_thigh" />
                    <body name="FR_calf" pos="0 -0.10009 -0.36">
                        <inertial pos="-0.00437397 -4.12835e-05 -0.157764"
                            quat="0.708075 1.33188e-05 0.0004089 0.706137" mass="0.75211"
                            diaginertia="0.0115786 0.0115192 0.000167844" />
                        <joint name="FR_calf_joint" pos="0 0 0" axis="0 -1 0" />
                        <geom type="mesh" contype="0" conaffinity="0" group="1" density="0"
                            rgba="0.898039 0.917647 0.929412 1" mesh="FR_calf" />
                        <geom type="mesh" rgba="0.898039 0.917647 0.929412 1" mesh="FR_calf" />
                        <geom pos="-0.00054829 0 -0.36" type="mesh" contype="0" conaffinity="0"
                            group="1" density="0"
                            rgba="1 1 1 1" mesh="FR_foot" />
                        <geom name="toe1_contact" type="sphere" size="0.015"
                            pos="-0.00054829 0 -0.36" rgba="0.7 0.7 0.7 0.7"
                            mass="0.10321" contype="1" conaffinity="1" priority="1" />
                        <site name="site_forcesensor1" pos="-0.00054829 0 -0.36" />
                    </body>
                </body>
            </body>
            <body name="RR_hip" pos="-0.244 -0.115 0">
                <inertial pos="-0.05057 0.046982 -1e-06"
                    quat="0.673113 0.673131 -0.216475 -0.216685" mass="1.656"
                    diaginertia="0.00276441 0.00265385 0.0019183" />
                <joint name="RR_hip_joint" pos="0 0 0" axis="1 0 0" />
                <geom type="mesh" contype="0" conaffinity="0" group="1" density="0"
                    rgba="0.89804 0.91765 0.92941 1"
                    mesh="RR_hip" />
                <geom type="mesh" rgba="0.89804 0.91765 0.92941 1" mesh="RR_hip" />
                <body name="RR_thigh" pos="-0.056 0.018587 0">
                    <inertial pos="-0.00063 -0.0201 -0.15827"
                        quat="0.447929 -0.0173336 -0.0144553 0.893784"
                        mass="1.337" diaginertia="0.0188849 0.0188331 0.00080071" />
                    <joint name="RR_thigh_joint" pos="0 0 0" axis="0 -1 0" />
                    <geom type="mesh" contype="0" conaffinity="0" group="1" density="0"
                        rgba="0.79216 0.81961 0.93333 1"
                        mesh="RR_thigh" />
                    <geom type="mesh" rgba="0.79216 0.81961 0.93333 1" mesh="RR_thigh" />
                    <body name="RR_calf" pos="0 -0.10009 -0.36">
                        <inertial pos="-0.00437397 -4.12848e-05 -0.157764"
                            quat="0.708075 1.33058e-05 0.0004089 0.706137" mass="0.75211"
                            diaginertia="0.0115786 0.0115192 0.000167844" />
                        <joint name="RR_calf_joint" pos="0 0 0" axis="0 -1 0" />
                        <geom type="mesh" contype="0" conaffinity="0" group="1" density="0"
                            rgba="0.89804 0.91765 0.92941 1" mesh="RR_calf" />
                        <geom type="mesh" rgba="0.89804 0.91765 0.92941 1" mesh="RR_calf" />
                        <geom pos="-0.00054828 0 -0.36" type="mesh" contype="0" conaffinity="0"
                            group="1" density="0"
                            rgba="1 1 1 1" mesh="RR_foot" />
                        <geom name="toe2_contact" type="sphere" size="0.015"
                            pos="-0.00054828 0 -0.36" rgba="0.7 0.7 0.7 0.7"
                            mass="0.10321" contype="1" conaffinity="1" priority="1" />
                        <site name="site_forcesensor2" pos="-0.00054828 0 -0.36" />
                    </body>
                </body>
            </body>
            <body name="FL_hip" pos="0.244 0.115 0">
                <inertial pos="0.05057 -0.046982 -1e-06"
                    quat="0.673131 0.673113 -0.216685 -0.216475" mass="1.656"
                    diaginertia="0.00276441 0.00265385 0.0019183" />
                <joint name="FL_hip_joint" pos="0 0 0" axis="1 0 0" />
                <geom type="mesh" contype="0" conaffinity="0" group="1" density="0"
                    rgba="0.89804 0.91765 0.92941 1"
                    mesh="FL_hip" />
                <geom type="mesh" rgba="0.89804 0.91765 0.92941 1" mesh="FL_hip" />
                <body name="FL_thigh" pos="0.056 -0.018587 0">
                    <inertial pos="-0.00063 0.0201 -0.15827"
                        quat="0.447819 -0.0173309 -0.0144618 0.893839" mass="1.337"
                        diaginertia="0.0188849 0.0188331 0.000800664" />
                    <joint name="FL_thigh_joint" pos="0 0 0" axis="0 -1 0" />
                    <geom type="mesh" contype="0" conaffinity="0" group="1" density="0"
                        rgba="0.79216 0.81961 0.93333 1"
                        mesh="FL_thigh" />
                    <geom type="mesh" rgba="0.79216 0.81961 0.93333 1" mesh="FL_thigh" />
                    <body name="FL_calf" pos="0 0.10009 -0.36">
                        <inertial pos="-0.00437397 1.36069e-05 -0.157764"
                            quat="0.706818 0.000275735 0.00014696 0.707395" mass="0.75211"
                            diaginertia="0.0115786 0.0115192 0.00016784" />
                        <joint name="FL_calf_joint" pos="0 0 0" axis="0 -1 0" />
                        <geom type="mesh" contype="0" conaffinity="0" group="1" density="0"
                            rgba="0.89804 0.91765 0.92941 1" mesh="FL_calf" />
                        <geom type="mesh" rgba="0.89804 0.91765 0.92941 1" mesh="FL_calf" />
                        <geom pos="-0.00054828 0 -0.36" type="mesh" contype="0" conaffinity="0"
                            group="1" density="0"
                            rgba="1 1 1 1" mesh="FL_foot" />
                        <geom name="toe3_contact" type="sphere" size="0.015"
                            pos="-0.00054828 0 -0.36" rgba="0.7 0.7 0.7 0.7"
                            mass="0.10321" contype="1" conaffinity="1" priority="1" />
                        <site name="site_forcesensor3" pos="-0.00054828 0 -0.36" />
                    </body>
                </body>
            </body>
            <body name="RL_hip" pos="-0.244 0.115 0">
                <inertial pos="-0.05057 -0.046982 1e-06" quat="0.673113 0.673131 0.216475 0.216685"
                    mass="1.656"
                    diaginertia="0.00276441 0.00265385 0.0019183" />
                <joint name="RL_hip_joint" pos="0 0 0" axis="1 0 0" />
                <geom type="mesh" contype="0" conaffinity="0" group="1" density="0"
                    rgba="0.89804 0.91765 0.92941 1"
                    mesh="RL_hip" />
                <geom type="mesh" rgba="0.89804 0.91765 0.92941 1" mesh="RL_hip" />
                <body name="RL_thigh" pos="-0.056 -0.018588 0">
                    <inertial pos="-0.00063 0.0201 -0.15827"
                        quat="0.447819 -0.0173309 -0.0144618 0.893839" mass="1.337"
                        diaginertia="0.0188849 0.0188331 0.000800664" />
                    <joint name="RL_thigh_joint" pos="0 0 0" axis="0 -1 0" />
                    <geom type="mesh" contype="0" conaffinity="0" group="1" density="0"
                        rgba="0.89804 0.91765 0.92941 1"
                        mesh="RL_thigh" />
                    <geom type="mesh" rgba="0.89804 0.91765 0.92941 1" mesh="RL_thigh" />
                    <body name="RL_calf" pos="0 0.10009 -0.36">
                        <inertial pos="-0.00437397 6.84984e-05 -0.157764"
                            quat="0.705558 0.000537227 -0.000115922 0.708652" mass="0.75211"
                            diaginertia="0.0115786 0.0115192 0.000167852" />
                        <joint name="RL_calf_joint" pos="0 0 0" axis="0 -1 0" />
                        <geom type="mesh" contype="0" conaffinity="0" group="1" density="0"
                            rgba="0.89804 0.91765 0.92941 1" mesh="RL_calf" />
                        <geom type="mesh" rgba="0.89804 0.91765 0.92941 1" mesh="RL_calf" />
                        <geom pos="-0.00054828 0 -0.36" type="mesh" contype="0" conaffinity="0"
                            group="1" density="0"
                            rgba="1 1 1 1" mesh="RL_foot" />
                        <geom name="toe4_contact" type="sphere" size="0.015"
                            pos="-0.00054828 0 -0.36" rgba="0.7 0.7 0.7 0.7"
                            mass="0.10321" contype="1" conaffinity="1" priority="1" />
                        <site name="site_forcesensor4" pos="-0.00054828 0 -0.36" />
                    </body>
                </body>
            </body>
        </body>
    </worldbody>
    <actuator>
        <motor name="FR_hip_joint" joint="FR_hip_joint" gear="1" ctrllimited="true"
            ctrlrange="-180 180" />
        <motor name="RR_hip_joint" joint="RR_hip_joint" gear="1" ctrllimited="true"
            ctrlrange="-180 180" />
        <motor name="FL_hip_joint" joint="FL_hip_joint" gear="1" ctrllimited="true"
            ctrlrange="-180 180" />
        <motor name="RL_hip_joint" joint="RL_hip_joint" gear="1" ctrllimited="true"
            ctrlrange="-180 180" />

        <motor name="FR_thigh_joint" joint="FR_thigh_joint" gear="1" ctrllimited="true"
            ctrlrange="-180 180" />
        <motor name="RR_thigh_joint" joint="RR_thigh_joint" gear="1" ctrllimited="true"
            ctrlrange="-180 180" />
        <motor name="FL_thigh_joint" joint="FL_thigh_joint" gear="1" ctrllimited="true"
            ctrlrange="-180 180" />
        <motor name="RL_thigh_joint" joint="RL_thigh_joint" gear="1" ctrllimited="true"
            ctrlrange="-180 180" />

        <motor name="FR_calf_joint" joint="FR_calf_joint" gear="1" ctrllimited="true"
            ctrlrange="-180 180" />
        <motor name="RR_calf_joint" joint="RR_calf_joint" gear="1" ctrllimited="true"
            ctrlrange="-180 180" />
        <motor name="FL_calf_joint" joint="FL_calf_joint" gear="1" ctrllimited="true"
            ctrlrange="-180 180" />
        <motor name="RL_calf_joint" joint="RL_calf_joint" gear="1" ctrllimited="true"
            ctrlrange="-180 180" />

    </actuator>

    <sensor>
        <force name="forcesensor1" site="site_forcesensor1" cutoff="5000.0" />
        <force name="forcesensor2" site="site_forcesensor2" cutoff="5000.0" />
        <force name="forcesensor3" site="site_forcesensor3" cutoff="5000.0" />
        <force name="forcesensor4" site="site_forcesensor4" cutoff="5000.0" />

        <accelerometer name="imu_acc" site="site_imu" />
        <gyro name="imu_gyro" site="site_imu" />
    </sensor>

    <contact>
        <exclude body1="base_link" body2="FR_thigh" />
        <exclude body1="base_link" body2="RR_thigh" />
        <exclude body1="base_link" body2="FL_thigh" />
        <exclude body1="base_link" body2="RL_thigh" />
    </contact>
</mujoco>